Workbook

Sheet RINGS_SUMMARY
A1: Symbol | B1: Brand | C1: Group1 | D1: Group2 | E1: LWC+PE | F1: Monika | G1: STOCKS- | H1: SL1642509 | I1: SL1692601 | J1: SUP25459 | K1: Order_1 | L1: Order_2 | M1: Order_3 | N1: Total Available | O1: NEED_M1 | P1: NEED_M2 | Q1: NEED_M3 | R1: NEED_M4 | S1: NEED_M5 | T1: NEED_M6 | U1: NEED_M7 | V1: NEED_M8 | W1: NEED_M9 | X1: NEED_M10 | Y1: NEED_M11 | Z1: NEED_M12 | AA1: NEED_M13 | AB1: NEED_M14 | AC1: NEED_M15 | AD1: NEED_M16 | AE1: NEED_M17 | AF1: NEED_M18 | AG1: NEED_M19 | AH1: NEED_M20 | AI1: NEED_M21 | AJ1: NEED_M22 | AK1: NEED_M23 | AL1: NEED_M24 | AM1: NEED_M25 | AN1: NEED_M26 | AO1: NEED_M27 | AP1: NEED_M28 | AQ1: NEED_M29 | AR1: NEED_M30
A2: PR-CHE-49-1405-000-SET | B2: CHE | C2: 1405 | D2: 19-1405-000 | N2: =SUM(E2:M2) -> 0 | O2: =MIN(0, N2+(IFERROR(IF(1*INDEX('UA-normalized'!$D:$D, MATCH($A2, 'UA-normalized'!$A:$A, 0))-INDEX('UA-normalized'!$E:$E, MATCH($A2, 'UA-normalized'!$A:$A, 0))>0, -(1*INDEX('UA-normalized'!$D:$D, MATCH($A2, 'UA-normalized'!$A:$A, 0))-INDEX('UA-normalized'!$E:$E, MATCH($A2, 'UA-normalized'!$A:$A, 0))), 0), 0))+(IFERROR(IF(1*INDEX('KZ-normalized'!$D:$D, MATCH($A2, 'KZ-normalized'!$A:$A, 0))-INDEX('KZ-normalized'!$E:$E, MATCH($A2, 'KZ-normalized'!$A:$A, 0))>0, -(1*INDEX('KZ-normalized'!$D:$D, MATCH($A2, 'KZ-normalized'!$A:$A, 0))-INDEX('KZ-normalized'!$E:$E, MATCH($A2, 'KZ-normalized'!$A:$A, 0))), 0), 0))+(IFERROR(IF(1*INDEX('UZ-normalized'!$D:$D, MATCH($A2, 'UZ-normalized'!$A:$A, 0))-INDEX('UZ-normalized'!$E:$E, MATCH($A2, 'UZ-normalized'!$A:$A, 0))>0, -(1*INDEX('UZ-normalized'!$D:$D, MATCH($A2, 'UZ-normalized'!$A:$A, 0))-INDEX('UZ-normalized'!$E:$E, MATCH($A2, 'UZ-normalized'!$A:$A, 0))), 0), 0))) -> 0 | P2: =MIN(0, N2+(IFERROR(IF(2*INDEX('UA-normalized'!$D:$D, MATCH($A2, 'UA-normalized'!$A:$A, 0))-INDEX('UA-normalized'!$E:$E, MATCH($A2, 'UA-normalized'!$A:$A, 0))>0, -(2*INDEX('UA-normalized'!$D:$D, MATCH($A2, 'UA-normalized'!$A:$A, 0))-INDEX('UA-normalized'!$E:$E, MATCH($A2, 'UA-normalized'!$A:$A, 0))), 0), 0))+(IFERROR(IF(2*INDEX('KZ-normalized'!$D:$D, MATCH($A2, 'KZ-normalized'!$A:$A, 0))-INDEX('KZ-normalized'!$E:$E, MATCH($A2, 'KZ-normalized'!$A:$A, 0))>0, -(2*INDEX('KZ-normalized'!$D:$D, MATCH($A2, 'KZ-normalized'!$A:$A, 0))-INDEX('KZ-normalized'!$E:$E, MATCH($A2, 'KZ-normalized'!$A:$A, 0))), 0), 0))+(IFERROR(IF(2*INDEX('UZ-normalized'!$D:$D, MATCH($A2, 'UZ-normalized'!$A:$A, 0))-INDEX('UZ-normalized'!$E:$E, MATCH($A2, 'UZ-normalized'!$A:$A, 0))>0, -(2*INDEX('UZ-normalized'!$D:$D, MATCH($A2, 'UZ-normalized'!$A:$A, 0))-INDEX('UZ-normalized'!$E:$E, MATCH($A2, 'UZ-normalized'!$A:$A, 0))), 0), 0))) -> 0 | Q2: =MIN(0, N2+(IFERROR(IF(3*INDEX('UA-normalized'!$D:$D, MATCH($A2, 'UA-normalized'!$A:$A, 0))-INDEX('UA-normalized'!$E:$E, MATCH($A2, 'UA-normalized'!$A:$A, 0))>0, -(3*INDEX('UA-normalized'!$D:$D, MATCH($A2, 'UA-normalized'!$A:$A, 0))-INDEX('UA-normalized'!$E:$E, MATCH($A2, 'UA-normalized'!$A:$A, 0))), 0), 0))+(IFERROR(IF(3*INDEX('KZ-normalized'!$D:$D, MATCH($A2, 'KZ-normalized'!$A:$A, 0))-INDEX('KZ-normalized'!$E:$E, MATCH($A2, 'KZ-normalized'!$A:$A, 0))>0, -(3*INDEX('KZ-normalized'!$D:$D, MATCH($A2, 'KZ-normalized'!$A:$A, 0))-INDEX('KZ-normalized'!$E:$E, MATCH($A2, 'KZ-normalized'!$A:$A, 0))), 0), 0))+(IFERROR(IF(3*INDEX('UZ-normalized'!$D:$D, MATCH($A2, 'UZ-normalized'!$A:$A, 0))-INDEX('UZ-normalized'!$E:$E, MATCH($A2, 'UZ-normalized'!$A:$A, 0))>0, -(3*INDEX('UZ-normalized'!$D:$D, MATCH($A2, 'UZ-normalized'!$A:$A, 0))-INDEX('UZ-normalized'!$E:$E, MATCH($A2, 'UZ-normalized'!$A:$A, 0))), 0), 0))) -> 0 | R2: =MIN(0, N2+(IFERROR(IF(4*INDEX('UA-normalized'!$D:$D, MATCH($A2, 'UA-normalized'!$A:$A, 0))-INDEX('UA-normalized'!$E:$E, MATCH($A2, 'UA-normalized'!$A:$A, 0))>0, -(4*INDEX('UA-normalized'!$D:$D, MATCH($A2, 'UA-normalized'!$A:$A, 0))-INDEX('UA-normalized'!$E:$E, MATCH($A2, 'UA-normalized'!$A:$A, 0))), 0), 0))+(IFERROR(IF(4*INDEX('KZ-normalized'!$D:$D, MATCH($A2, 'KZ-normalized'!$A:$A, 0))-INDEX('KZ-normalized'!$E:$E, MATCH($A2, 'KZ-normalized'!$A:$A, 0))>0, -(4*INDEX('KZ-normalized'!$D:$D, MATCH($A2, 'KZ-normalized'!$A:$A, 0))-INDEX('KZ-normalized'!$E:$E, MATCH($A2, 'KZ-normalized'!$A:$A, 0))), 0), 0))+(IFERROR(IF(4*INDEX('UZ-normalized'!$D:$D, MATCH($A2, 'UZ-normalized'!$A:$A, 0))-INDEX('UZ-normalized'!$E:$E, MATCH($A2, 'UZ-normalized'!$A:$A, 0))>0, -(4*INDEX('UZ-normalized'!$D:$D, MATCH($A2, 'UZ-normalized'!$A:$A, 0))-INDEX('UZ-normalized'!$E:$E, MATCH($A2, 'UZ-normalized'!$A:$A, 0))), 0), 0))) -> -18 | S2: =MIN(0, N2+(IFERROR(IF(5*INDEX('UA-normalized'!$D:$D, MATCH($A2, 'UA-normalized'!$A:$A, 0))-INDEX('UA-normalized'!$E:$E, MATCH($A2, 'UA-normalized'!$A:$A, 0))>0, -(5*INDEX('UA-normalized'!$D:$D, MATCH($A2, 'UA-normalized'!$A:$A, 0))-INDEX('UA-normalized'!$E:$E, MATCH($A2, 'UA-normalized'!$A:$A, 0))), 0), 0))+(IFERROR(IF(5*INDEX('KZ-normalized'!$D:$D, MATCH($A2, 'KZ-normalized'!$A:$A, 0))-INDEX('KZ-normalized'!$E:$E, MATCH($A2, 'KZ-normalized'!$A:$A, 0))>0, -(5*INDEX('KZ-normalized'!$D:$D, MATCH($A2, 'KZ-normalized'!$A:$A, 0))-INDEX('KZ-normalized'!$E:$E, MATCH($A2, 'KZ-normalized'!$A:$A, 0))), 0), 0))+(IFERROR(IF(5*INDEX('UZ-normalized'!$D:$D, MATCH($A2, 'UZ-normalized'!$A:$A, 0))-INDEX('UZ-normalized'!$E:$E, MATCH($A2, 'UZ-normalized'!$A:$A, 0))>0, -(5*INDEX('UZ-normalized'!$D:$D, MATCH($A2, 'UZ-normalized'!$A:$A, 0))-INDEX('UZ-normalized'!$E:$E, MATCH($A2, 'UZ-normalized'!$A:$A, 0))), 0), 0))) -> -78 | T2: =MIN(0, N2+(IFERROR(IF(6*INDEX('UA-normalized'!$D:$D, MATCH($A2, 'UA-normalized'!$A:$A, 0))-INDEX('UA-normalized'!$E:$E, MATCH($A2, 'UA-normalized'!$A:$A, 0))>0, -(6*INDEX('UA-normalized'!$D:$D, MATCH($A2, 'UA-normalized'!$A:$A, 0))-INDEX('UA-normalized'!$E:$E, MATCH($A2, 'UA-normalized'!$A:$A, 0))), 0), 0))+(IFERROR(IF(6*INDEX('KZ-normalized'!$D:$D, MATCH($A2, 'KZ-normalized'!$A:$A, 0))-INDEX('KZ-normalized'!$E:$E, MATCH($A2, 'KZ-normalized'!$A:$A, 0))>0, -(6*INDEX('KZ-normalized'!$D:$D, MATCH($A2, 'KZ-normalized'!$A:$A, 0))-INDEX('KZ-normalized'!$E:$E, MATCH($A2, 'KZ-normalized'!$A:$A, 0))), 0), 0))+(IFERROR(IF(6*INDEX('UZ-normalized'!$D:$D, MATCH($A2, 'UZ-normalized'!$A:$A, 0))-INDEX('UZ-normalized'!$E:$E, MATCH($A2, 'UZ-normalized'!$A:$A, 0))>0, -(6*INDEX('UZ-normalized'!$D:$D, MATCH($A2, 'UZ-normalized'!$A:$A, 0))-INDEX('UZ-normalized'!$E:$E, MATCH($A2, 'UZ-normalized'!$A:$A, 0))), 0), 0))) -> -138 | U2: =MIN(0, N2+(IFERROR(IF(7*INDEX('UA-normalized'!$D:$D, MATCH($A2, 'UA-normalized'!$A:$A, 0))-INDEX('UA-normalized'!$E:$E, MATCH($A2, 'UA-normalized'!$A:$A, 0))>0, -(7*INDEX('UA-normalized'!$D:$D, MATCH($A2, 'UA-normalized'!$A:$A, 0))-INDEX('UA-normalized'!$E:$E, MATCH($A2, 'UA-normalized'!$A:$A, 0))), 0), 0))+(IFERROR(IF(7*INDEX('KZ-normalized'!$D:$D, MATCH($A2, 'KZ-normalized'!$A:$A, 0))-INDEX('KZ-normalized'!$E:$E, MATCH($A2, 'KZ-normalized'!$A:$A, 0))>0, -(7*INDEX('KZ-normalized'!$D:$D, MATCH($A2, 'KZ-normalized'!$A:$A, 0))-INDEX('KZ-normalized'!$E:$E, MATCH($A2, 'KZ-normalized'!$A:$A, 0))), 0), 0))+(IFERROR(IF(7*INDEX('UZ-normalized'!$D:$D, MATCH($A2, 'UZ-normalized'!$A:$A, 0))-INDEX('UZ-normalized'!$E:$E, MATCH($A2, 'UZ-normalized'!$A:$A, 0))>0, -(7*INDEX('UZ-normalized'!$D:$D, MATCH($A2, 'UZ-normalized'!$A:$A, 0))-INDEX('UZ-normalized'!$E:$E, MATCH($A2, 'UZ-normalized'!$A:$A, 0))), 0), 0))) -> -198 | V2: =MIN(0, N2+(IFERROR(IF(8*INDEX('UA-normalized'!$D:$D, MATCH($A2, 'UA-normalized'!$A:$A, 0))-INDEX('UA-normalized'!$E:$E, MATCH($A2, 'UA-normalized'!$A:$A, 0))>0, -(8*INDEX('UA-normalized'!$D:$D, MATCH($A2, 'UA-normalized'!$A:$A, 0))-INDEX('UA-normalized'!$E:$E, MATCH($A2, 'UA-normalized'!$A:$A, 0))), 0), 0))+(IFERROR(IF(8*INDEX('KZ-normalized'!$D:$D, MATCH($A2, 'KZ-normalized'!$A:$A, 0))-INDEX('KZ-normalized'!$E:$E, MATCH($A2, 'KZ-normalized'!$A:$A, 0))>0, -(8*INDEX('KZ-normalized'!$D:$D, MATCH($A2, 'KZ-normalized'!$A:$A, 0))-INDEX('KZ-normalized'!$E:$E, MATCH($A2, 'KZ-normalized'!$A:$A, 0))), 0), 0))+(IFERROR(IF(8*INDEX('UZ-normalized'!$D:$D, MATCH($A2, 'UZ-normalized'!$A:$A, 0))-INDEX('UZ-normalized'!$E:$E, MATCH($A2, 'UZ-normalized'!$A:$A, 0))>0, -(8*INDEX('UZ-normalized'!$D:$D, MATCH($A2, 'UZ-normalized'!$A:$A, 0))-INDEX('UZ-normalized'!$E:$E, MATCH($A2, 'UZ-normalized'!$A:$A, 0))), 0), 0))) -> -258 | W2: =MIN(0, N2+(IFERROR(IF(9*INDEX('UA-normalized'!$D:$D, MATCH($A2, 'UA-normalized'!$A:$A, 0))-INDEX('UA-normalized'!$E:$E, MATCH($A2, 'UA-normalized'!$A:$A, 0))>0, -(9*INDEX('UA-normalized'!$D:$D, MATCH($A2, 'UA-normalized'!$A:$A, 0))-INDEX('UA-normalized'!$E:$E, MATCH($A2, 'UA-normalized'!$A:$A, 0))), 0), 0))+(IFERROR(IF(9*INDEX('KZ-normalized'!$D:$D, MATCH($A2, 'KZ-normalized'!$A:$A, 0))-INDEX('KZ-normalized'!$E:$E, MATCH($A2, 'KZ-normalized'!$A:$A, 0))>0, -(9*INDEX('KZ-normalized'!$D:$D, MATCH($A2, 'KZ-normalized'!$A:$A, 0))-INDEX('KZ-normalized'!$E:$E, MATCH($A2, 'KZ-normalized'!$A:$A, 0))), 0), 0))+(IFERROR(IF(9*INDEX('UZ-normalized'!$D:$D, MATCH($A2, 'UZ-normalized'!$A:$A, 0))-INDEX('UZ-normalized'!$E:$E, MATCH($A2, 'UZ-normalized'!$A:$A, 0))>0, -(9*INDEX('UZ-normalized'!$D:$D, MATCH($A2, 'UZ-normalized'!$A:$A, 0))-INDEX('UZ-normalized'!$E:$E, MATCH($A2, 'UZ-normalized'!$A:$A, 0))), 0), 0))) -> -318 | X2: =MIN(0, N2+(IFERROR(IF(10*INDEX('UA-normalized'!$D:$D, MATCH($A2, 'UA-normalized'!$A:$A, 0))-INDEX('UA-normalized'!$E:$E, MATCH($A2, 'UA-normalized'!$A:$A, 0))>0, -(10*INDEX('UA-normalized'!$D:$D, MATCH($A2, 'UA-normalized'!$A:$A, 0))-INDEX('UA-normalized'!$E:$E, MATCH($A2, 'UA-normalized'!$A:$A, 0))), 0), 0))+(IFERROR(IF(10*INDEX('KZ-normalized'!$D:$D, MATCH($A2, 'KZ-normalized'!$A:$A, 0))-INDEX('KZ-normalized'!$E:$E, MATCH($A2, 'KZ-normalized'!$A:$A, 0))>0, -(10*INDEX('KZ-normalized'!$D:$D, MATCH($A2, 'KZ-normalized'!$A:$A, 0))-INDEX('KZ-normalized'!$E:$E, MATCH($A2, 'KZ-normalized'!$A:$A, 0))), 0), 0))+(IFERROR(IF(10*INDEX('UZ-normalized'!$D:$D, MATCH($A2, 'UZ-normalized'!$A:$A, 0))-INDEX('UZ-normalized'!$E:$E, MATCH($A2, 'UZ-normalized'!$A:$A, 0))>0, -(10*INDEX('UZ-normalized'!$D:$D, MATCH($A2, 'UZ-normalized'!$A:$A, 0))-INDEX('UZ-normalized'!$E:$E, MATCH($A2, 'UZ-normalized'!$A:$A, 0))), 0), 0))) -> -378 | Y2: =MIN(0, N2+(IFERROR(IF(11*INDEX('UA-normalized'!$D:$D, MATCH($A2, 'UA-normalized'!$A:$A, 0))-INDEX('UA-normalized'!$E:$E, MATCH($A2, 'UA-normalized'!$A:$A, 0))>0, -(11*INDEX('UA-normalized'!$D:$D, MATCH($A2, 'UA-normalized'!$A:$A, 0))-INDEX('UA-normalized'!$E:$E, MATCH($A2, 'UA-normalized'!$A:$A, 0))), 0), 0))+(IFERROR(IF(11*INDEX('KZ-normalized'!$D:$D, MATCH($A2, 'KZ-normalized'!$A:$A, 0))-INDEX('KZ-normalized'!$E:$E, MATCH($A2, 'KZ-normalized'!$A:$A, 0))>0, -(11*INDEX('KZ-normalized'!$D:$D, MATCH($A2, 'KZ-normalized'!$A:$A, 0))-INDEX('KZ-normalized'!$E:$E, MATCH($A2, 'KZ-normalized'!$A:$A, 0))), 0), 0))+(IFERROR(IF(11*INDEX('UZ-normalized'!$D:$D, MATCH($A2, 'UZ-normalized'!$A:$A, 0))-INDEX('UZ-normalized'!$E:$E, MATCH($A2, 'UZ-normalized'!$A:$A, 0))>0, -(11*INDEX('UZ-normalized'!$D:$D, MATCH($A2, 'UZ-normalized'!$A:$A, 0))-INDEX('UZ-normalized'!$E:$E, MATCH($A2, 'UZ-normalized'!$A:$A, 0))), 0), 0))) -> -438 | Z2: =MIN(0, N2+(IFERROR(IF(12*INDEX('UA-normalized'!$D:$D, MATCH($A2, 'UA-normalized'!$A:$A, 0))-INDEX('UA-normalized'!$E:$E, MATCH($A2, 'UA-normalized'!$A:$A, 0))>0, -(12*INDEX('UA-normalized'!$D:$D, MATCH($A2, 'UA-normalized'!$A:$A, 0))-INDEX('UA-normalized'!$E:$E, MATCH($A2, 'UA-normalized'!$A:$A, 0))), 0), 0))+(IFERROR(IF(12*INDEX('KZ-normalized'!$D:$D, MATCH($A2, 'KZ-normalized'!$A:$A, 0))-INDEX('KZ-normalized'!$E:$E, MATCH($A2, 'KZ-normalized'!$A:$A, 0))>0, -(12*INDEX('KZ-normalized'!$D:$D, MATCH($A2, 'KZ-normalized'!$A:$A, 0))-INDEX('KZ-normalized'!$E:$E, MATCH($A2, 'KZ-normalized'!$A:$A, 0))), 0), 0))+(IFERROR(IF(12*INDEX('UZ-normalized'!$D:$D, MATCH($A2, 'UZ-normalized'!$A:$A, 0))-INDEX('UZ-normalized'!$E:$E, MATCH($A2, 'UZ-normalized'!$A:$A, 0))>0, -(12*INDEX('UZ-normalized'!$D:$D, MATCH($A2, 'UZ-normalized'!$A:$A, 0))-INDEX('UZ-normalized'!$E:$E, MATCH($A2, 'UZ-normalized'!$A:$A, 0))), 0), 0))) -> -498 | AA2: =MIN(0, N2+(IFERROR(IF(13*INDEX('UA-normalized'!$D:$D, MATCH($A2, 'UA-normalized'!$A:$A, 0))-INDEX('UA-normalized'!$E:$E, MATCH($A2, 'UA-normalized'!$A:$A, 0))>0, -(13*INDEX('UA-normalized'!$D:$D, MATCH($A2, 'UA-normalized'!$A:$A, 0))-INDEX('UA-normalized'!$E:$E, MATCH($A2, 'UA-normalized'!$A:$A, 0))), 0), 0))+(IFERROR(IF(13*INDEX('KZ-normalized'!$D:$D, MATCH($A2, 'KZ-normalized'!$A:$A, 0))-INDEX('KZ-normalized'!$E:$E, MATCH($A2, 'KZ-normalized'!$A:$A, 0))>0, -(13*INDEX('KZ-normalized'!$D:$D, MATCH($A2, 'KZ-normalized'!$A:$A, 0))-INDEX('KZ-normalized'!$E:$E, MATCH($A2, 'KZ-normalized'!$A:$A, 0))), 0), 0))+(IFERROR(IF(13*INDEX('UZ-normalized'!$D:$D, MATCH($A2, 'UZ-normalized'!$A:$A, 0))-INDEX('UZ-normalized'!$E:$E, MATCH($A2, 'UZ-normalized'!$A:$A, 0))>0, -(13*INDEX('UZ-normalized'!$D:$D, MATCH($A2, 'UZ-normalized'!$A:$A, 0))-INDEX('UZ-normalized'!$E:$E, MATCH($A2, 'UZ-normalized'!$A:$A, 0))), 0), 0))) -> -558 | AB2: =MIN(0, N2+(IFERROR(IF(14*INDEX('UA-normalized'!$D:$D, MATCH($A2, 'UA-normalized'!$A:$A, 0))-INDEX('UA-normalized'!$E:$E, MATCH($A2, 'UA-normalized'!$A:$A, 0))>0, -(14*INDEX('UA-normalized'!$D:$D, MATCH($A2, 'UA-normalized'!$A:$A, 0))-INDEX('UA-normalized'!$E:$E, MATCH($A2, 'UA-normalized'!$A:$A, 0))), 0), 0))+(IFERROR(IF(14*INDEX('KZ-normalized'!$D:$D, MATCH($A2, 'KZ-normalized'!$A:$A, 0))-INDEX('KZ-normalized'!$E:$E, MATCH($A2, 'KZ-normalized'!$A:$A, 0))>0, -(14*INDEX('KZ-normalized'!$D:$D, MATCH($A2, 'KZ-normalized'!$A:$A, 0))-INDEX('KZ-normalized'!$E:$E, MATCH($A2, 'KZ-normalized'!$A:$A, 0))), 0), 0))+(IFERROR(IF(14*INDEX('UZ-normalized'!$D:$D, MATCH($A2, 'UZ-normalized'!$A:$A, 0))-INDEX('UZ-normalized'!$E:$E, MATCH($A2, 'UZ-normalized'!$A:$A, 0))>0, -(14*INDEX('UZ-normalized'!$D:$D, MATCH($A2, 'UZ-normalized'!$A:$A, 0))-INDEX('UZ-normalized'!$E:$E, MATCH($A2, 'UZ-normalized'!$A:$A, 0))), 0), 0))) -> -618 | AC2: =MIN(0, N2+(IFERROR(IF(15*INDEX('UA-normalized'!$D:$D, MATCH($A2, 'UA-normalized'!$A:$A, 0))-INDEX('UA-normalized'!$E:$E, MATCH($A2, 'UA-normalized'!$A:$A, 0))>0, -(15*INDEX('UA-normalized'!$D:$D, MATCH($A2, 'UA-normalized'!$A:$A, 0))-INDEX('UA-normalized'!$E:$E, MATCH($A2, 'UA-normalized'!$A:$A, 0))), 0), 0))+(IFERROR(IF(15*INDEX('KZ-normalized'!$D:$D, MATCH($A2, 'KZ-normalized'!$A:$A, 0))-INDEX('KZ-normalized'!$E:$E, MATCH($A2, 'KZ-normalized'!$A:$A, 0))>0, -(15*INDEX('KZ-normalized'!$D:$D, MATCH($A2, 'KZ-normalized'!$A:$A, 0))-INDEX('KZ-normalized'!$E:$E, MATCH($A2, 'KZ-normalized'!$A:$A, 0))), 0), 0))+(IFERROR(IF(15*INDEX('UZ-normalized'!$D:$D, MATCH($A2, 'UZ-normalized'!$A:$A, 0))-INDEX('UZ-normalized'!$E:$E, MATCH($A2, 'UZ-normalized'!$A:$A, 0))>0, -(15*INDEX('UZ-normalized'!$D:$D, MATCH($A2, 'UZ-normalized'!$A:$A, 0))-INDEX('UZ-normalized'!$E:$E, MATCH($A2, 'UZ-normalized'!$A:$A, 0))), 0), 0))) -> -678 | AD2: =MIN(0, N2+(IFERROR(IF(16*INDEX('UA-normalized'!$D:$D, MATCH($A2, 'UA-normalized'!$A:$A, 0))-INDEX('UA-normalized'!$E:$E, MATCH($A2, 'UA-normalized'!$A:$A, 0))>0, -(16*INDEX('UA-normalized'!$D:$D, MATCH($A2, 'UA-normalized'!$A:$A, 0))-INDEX('UA-normalized'!$E:$E, MATCH($A2, 'UA-normalized'!$A:$A, 0))), 0), 0))+(IFERROR(IF(16*INDEX('KZ-normalized'!$D:$D, MATCH($A2, 'KZ-normalized'!$A:$A, 0))-INDEX('KZ-normalized'!$E:$E, MATCH($A2, 'KZ-normalized'!$A:$A, 0))>0, -(16*INDEX('KZ-normalized'!$D:$D, MATCH($A2, 'KZ-normalized'!$A:$A, 0))-INDEX('KZ-normalized'!$E:$E, MATCH($A2, 'KZ-normalized'!$A:$A, 0))), 0), 0))+(IFERROR(IF(16*INDEX('UZ-normalized'!$D:$D, MATCH($A2, 'UZ-normalized'!$A:$A, 0))-INDEX('UZ-normalized'!$E:$E, MATCH($A2, 'UZ-normalized'!$A:$A, 0))>0, -(16*INDEX('UZ-normalized'!$D:$D, MATCH($A2, 'UZ-normalized'!$A:$A, 0))-INDEX('UZ-normalized'!$E:$E, MATCH($A2, 'UZ-normalized'!$A:$A, 0))), 0), 0))) -> -738 | AE2: =MIN(0, N2+(IFERROR(IF(17*INDEX('UA-normalized'!$D:$D, MATCH($A2, 'UA-normalized'!$A:$A, 0))-INDEX('UA-normalized'!$E:$E, MATCH($A2, 'UA-normalized'!$A:$A, 0))>0, -(17*INDEX('UA-normalized'!$D:$D, MATCH($A2, 'UA-normalized'!$A:$A, 0))-INDEX('UA-normalized'!$E:$E, MATCH($A2, 'UA-normalized'!$A:$A, 0))), 0), 0))+(IFERROR(IF(17*INDEX('KZ-normalized'!$D:$D, MATCH($A2, 'KZ-normalized'!$A:$A, 0))-INDEX('KZ-normalized'!$E:$E, MATCH($A2, 'KZ-normalized'!$A:$A, 0))>0, -(17*INDEX('KZ-normalized'!$D:$D, MATCH($A2, 'KZ-normalized'!$A:$A, 0))-INDEX('KZ-normalized'!$E:$E, MATCH($A2, 'KZ-normalized'!$A:$A, 0))), 0), 0))+(IFERROR(IF(17*INDEX('UZ-normalized'!$D:$D, MATCH($A2, 'UZ-normalized'!$A:$A, 0))-INDEX('UZ-normalized'!$E:$E, MATCH($A2, 'UZ-normalized'!$A:$A, 0))>0, -(17*INDEX('UZ-normalized'!$D:$D, MATCH($A2, 'UZ-normalized'!$A:$A, 0))-INDEX('UZ-normalized'!$E:$E, MATCH($A2, 'UZ-normalized'!$A:$A, 0))), 0), 0))) -> -798 | AF2: =MIN(0, N2+(IFERROR(IF(18*INDEX('UA-normalized'!$D:$D, MATCH($A2, 'UA-normalized'!$A:$A, 0))-INDEX('UA-normalized'!$E:$E, MATCH($A2, 'UA-normalized'!$A:$A, 0))>0, -(18*INDEX('UA-normalized'!$D:$D, MATCH($A2, 'UA-normalized'!$A:$A, 0))-INDEX('UA-normalized'!$E:$E, MATCH($A2, 'UA-normalized'!$A:$A, 0))), 0), 0))+(IFERROR(IF(18*INDEX('KZ-normalized'!$D:$D, MATCH($A2, 'KZ-normalized'!$A:$A, 0))-INDEX('KZ-normalized'!$E:$E, MATCH($A2, 'KZ-normalized'!$A:$A, 0))>0, -(18*INDEX('KZ-normalized'!$D:$D, MATCH($A2, 'KZ-normalized'!$A:$A, 0))-INDEX('KZ-normalized'!$E:$E, MATCH($A2, 'KZ-normalized'!$A:$A, 0))), 0), 0))+(IFERROR(IF(18*INDEX('UZ-normalized'!$D:$D, MATCH($A2, 'UZ-normalized'!$A:$A, 0))-INDEX('UZ-normalized'!$E:$E, MATCH($A2, 'UZ-normalized'!$A:$A, 0))>0, -(18*INDEX('UZ-normalized'!$D:$D, MATCH($A2, 'UZ-normalized'!$A:$A, 0))-INDEX('UZ-normalized'!$E:$E, MATCH($A2, 'UZ-normalized'!$A:$A, 0))), 0), 0))) -> -858 | AG2: =MIN(0, N2+(IFERROR(IF(19*INDEX('UA-normalized'!$D:$D, MATCH($A2, 'UA-normalized'!$A:$A, 0))-INDEX('UA-normalized'!$E:$E, MATCH($A2, 'UA-normalized'!$A:$A, 0))>0, -(19*INDEX('UA-normalized'!$D:$D, MATCH($A2, 'UA-normalized'!$A:$A, 0))-INDEX('UA-normalized'!$E:$E, MATCH($A2, 'UA-normalized'!$A:$A, 0))), 0), 0))+(IFERROR(IF(19*INDEX('KZ-normalized'!$D:$D, MATCH($A2, 'KZ-normalized'!$A:$A, 0))-INDEX('KZ-normalized'!$E:$E, MATCH($A2, 'KZ-normalized'!$A:$A, 0))>0, -(19*INDEX('KZ-normalized'!$D:$D, MATCH($A2, 'KZ-normalized'!$A:$A, 0))-INDEX('KZ-normalized'!$E:$E, MATCH($A2, 'KZ-normalized'!$A:$A, 0))), 0), 0))+(IFERROR(IF(19*INDEX('UZ-normalized'!$D:$D, MATCH($A2, 'UZ-normalized'!$A:$A, 0))-INDEX('UZ-normalized'!$E:$E, MATCH($A2, 'UZ-normalized'!$A:$A, 0))>0, -(19*INDEX('UZ-normalized'!$D:$D, MATCH($A2, 'UZ-normalized'!$A:$A, 0))-INDEX('UZ-normalized'!$E:$E, MATCH($A2, 'UZ-normalized'!$A:$A, 0))), 0), 0))) -> -918 | AH2: =MIN(0, N2+(IFERROR(IF(20*INDEX('UA-normalized'!$D:$D, MATCH($A2, 'UA-normalized'!$A:$A, 0))-INDEX('UA-normalized'!$E:$E, MATCH($A2, 'UA-normalized'!$A:$A, 0))>0, -(20*INDEX('UA-normalized'!$D:$D, MATCH($A2, 'UA-normalized'!$A:$A, 0))-INDEX('UA-normalized'!$E:$E, MATCH($A2, 'UA-normalized'!$A:$A, 0))), 0), 0))+(IFERROR(IF(20*INDEX('KZ-normalized'!$D:$D, MATCH($A2, 'KZ-normalized'!$A:$A, 0))-INDEX('KZ-normalized'!$E:$E, MATCH($A2, 'KZ-normalized'!$A:$A, 0))>0, -(20*INDEX('KZ-normalized'!$D:$D, MATCH($A2, 'KZ-normalized'!$A:$A, 0))-INDEX('KZ-normalized'!$E:$E, MATCH($A2, 'KZ-normalized'!$A:$A, 0))), 0), 0))+(IFERROR(IF(20*INDEX('UZ-normalized'!$D:$D, MATCH($A2, 'UZ-normalized'!$A:$A, 0))-INDEX('UZ-normalized'!$E:$E, MATCH($A2, 'UZ-normalized'!$A:$A, 0))>0, -(20*INDEX('UZ-normalized'!$D:$D, MATCH($A2, 'UZ-normalized'!$A:$A, 0))-INDEX('UZ-normalized'!$E:$E, MATCH($A2, 'UZ-normalized'!$A:$A, 0))), 0), 0))) -> -978 | AI2: =MIN(0, N2+(IFERROR(IF(21*INDEX('UA-normalized'!$D:$D, MATCH($A2, 'UA-normalized'!$A:$A, 0))-INDEX('UA-normalized'!$E:$E, MATCH($A2, 'UA-normalized'!$A:$A, 0))>0, -(21*INDEX('UA-normalized'!$D:$D, MATCH($A2, 'UA-normalized'!$A:$A, 0))-INDEX('UA-normalized'!$E:$E, MATCH($A2, 'UA-normalized'!$A:$A, 0))), 0), 0))+(IFERROR(IF(21*INDEX('KZ-normalized'!$D:$D, MATCH($A2, 'KZ-normalized'!$A:$A, 0))-INDEX('KZ-normalized'!$E:$E, MATCH($A2, 'KZ-normalized'!$A:$A, 0))>0, -(21*INDEX('KZ-normalized'!$D:$D, MATCH($A2, 'KZ-normalized'!$A:$A, 0))-INDEX('KZ-normalized'!$E:$E, MATCH($A2, 'KZ-normalized'!$A:$A, 0))), 0), 0))+(IFERROR(IF(21*INDEX('UZ-normalized'!$D:$D, MATCH($A2, 'UZ-normalized'!$A:$A, 0))-INDEX('UZ-normalized'!$E:$E, MATCH($A2, 'UZ-normalized'!$A:$A, 0))>0, -(21*INDEX('UZ-normalized'!$D:$D, MATCH($A2, 'UZ-normalized'!$A:$A, 0))-INDEX('UZ-normalized'!$E:$E, MATCH($A2, 'UZ-normalized'!$A:$A, 0))), 0), 0))) -> -1038 | AJ2: =MIN(0, N2+(IFERROR(IF(22*INDEX('UA-normalized'!$D:$D, MATCH($A2, 'UA-normalized'!$A:$A, 0))-INDEX('UA-normalized'!$E:$E, MATCH($A2, 'UA-normalized'!$A:$A, 0))>0, -(22*INDEX('UA-normalized'!$D:$D, MATCH($A2, 'UA-normalized'!$A:$A, 0))-INDEX('UA-normalized'!$E:$E, MATCH($A2, 'UA-normalized'!$A:$A, 0))), 0), 0))+(IFERROR(IF(22*INDEX('KZ-normalized'!$D:$D, MATCH($A2, 'KZ-normalized'!$A:$A, 0))-INDEX('KZ-normalized'!$E:$E, MATCH($A2, 'KZ-normalized'!$A:$A, 0))>0, -(22*INDEX('KZ-normalized'!$D:$D, MATCH($A2, 'KZ-normalized'!$A:$A, 0))-INDEX('KZ-normalized'!$E:$E, MATCH($A2, 'KZ-normalized'!$A:$A, 0))), 0), 0))+(IFERROR(IF(22*INDEX('UZ-normalized'!$D:$D, MATCH($A2, 'UZ-normalized'!$A:$A, 0))-INDEX('UZ-normalized'!$E:$E, MATCH($A2, 'UZ-normalized'!$A:$A, 0))>0, -(22*INDEX('UZ-normalized'!$D:$D, MATCH($A2, 'UZ-normalized'!$A:$A, 0))-INDEX('UZ-normalized'!$E:$E, MATCH($A2, 'UZ-normalized'!$A:$A, 0))), 0), 0))) -> -1098 | AK2: =MIN(0, N2+(IFERROR(IF(23*INDEX('UA-normalized'!$D:$D, MATCH($A2, 'UA-normalized'!$A:$A, 0))-INDEX('UA-normalized'!$E:$E, MATCH($A2, 'UA-normalized'!$A:$A, 0))>0, -(23*INDEX('UA-normalized'!$D:$D, MATCH($A2, 'UA-normalized'!$A:$A, 0))-INDEX('UA-normalized'!$E:$E, MATCH($A2, 'UA-normalized'!$A:$A, 0))), 0), 0))+(IFERROR(IF(23*INDEX('KZ-normalized'!$D:$D, MATCH($A2, 'KZ-normalized'!$A:$A, 0))-INDEX('KZ-normalized'!$E:$E, MATCH($A2, 'KZ-normalized'!$A:$A, 0))>0, -(23*INDEX('KZ-normalized'!$D:$D, MATCH($A2, 'KZ-normalized'!$A:$A, 0))-INDEX('KZ-normalized'!$E:$E, MATCH($A2, 'KZ-normalized'!$A:$A, 0))), 0), 0))+(IFERROR(IF(23*INDEX('UZ-normalized'!$D:$D, MATCH($A2, 'UZ-normalized'!$A:$A, 0))-INDEX('UZ-normalized'!$E:$E, MATCH($A2, 'UZ-normalized'!$A:$A, 0))>0, -(23*INDEX('UZ-normalized'!$D:$D, MATCH($A2, 'UZ-normalized'!$A:$A, 0))-INDEX('UZ-normalized'!$E:$E, MATCH($A2, 'UZ-normalized'!$A:$A, 0))), 0), 0))) -> -1158 | AL2: =MIN(0, N2+(IFERROR(IF(24*INDEX('UA-normalized'!$D:$D, MATCH($A2, 'UA-normalized'!$A:$A, 0))-INDEX('UA-normalized'!$E:$E, MATCH($A2, 'UA-normalized'!$A:$A, 0))>0, -(24*INDEX('UA-normalized'!$D:$D, MATCH($A2, 'UA-normalized'!$A:$A, 0))-INDEX('UA-normalized'!$E:$E, MATCH($A2, 'UA-normalized'!$A:$A, 0))), 0), 0))+(IFERROR(IF(24*INDEX('KZ-normalized'!$D:$D, MATCH($A2, 'KZ-normalized'!$A:$A, 0))-INDEX('KZ-normalized'!$E:$E, MATCH($A2, 'KZ-normalized'!$A:$A, 0))>0, -(24*INDEX('KZ-normalized'!$D:$D, MATCH($A2, 'KZ-normalized'!$A:$A, 0))-INDEX('KZ-normalized'!$E:$E, MATCH($A2, 'KZ-normalized'!$A:$A, 0))), 0), 0))+(IFERROR(IF(24*INDEX('UZ-normalized'!$D:$D, MATCH($A2, 'UZ-normalized'!$A:$A, 0))-INDEX('UZ-normalized'!$E:$E, MATCH($A2, 'UZ-normalized'!$A:$A, 0))>0, -(24*INDEX('UZ-normalized'!$D:$D, MATCH($A2, 'UZ-normalized'!$A:$A, 0))-INDEX('UZ-normalized'!$E:$E, MATCH($A2, 'UZ-normalized'!$A:$A, 0))), 0), 0))) -> -1218 | AM2: =MIN(0, N2+(IFERROR(IF(25*INDEX('UA-normalized'!$D:$D, MATCH($A2, 'UA-normalized'!$A:$A, 0))-INDEX('UA-normalized'!$E:$E, MATCH($A2, 'UA-normalized'!$A:$A, 0))>0, -(25*INDEX('UA-normalized'!$D:$D, MATCH($A2, 'UA-normalized'!$A:$A, 0))-INDEX('UA-normalized'!$E:$E, MATCH($A2, 'UA-normalized'!$A:$A, 0))), 0), 0))+(IFERROR(IF(25*INDEX('KZ-normalized'!$D:$D, MATCH($A2, 'KZ-normalized'!$A:$A, 0))-INDEX('KZ-normalized'!$E:$E, MATCH($A2, 'KZ-normalized'!$A:$A, 0))>0, -(25*INDEX('KZ-normalized'!$D:$D, MATCH($A2, 'KZ-normalized'!$A:$A, 0))-INDEX('KZ-normalized'!$E:$E, MATCH($A2, 'KZ-normalized'!$A:$A, 0))), 0), 0))+(IFERROR(IF(25*INDEX('UZ-normalized'!$D:$D, MATCH($A2, 'UZ-normalized'!$A:$A, 0))-INDEX('UZ-normalized'!$E:$E, MATCH($A2, 'UZ-normalized'!$A:$A, 0))>0, -(25*INDEX('UZ-normalized'!$D:$D, MATCH($A2, 'UZ-normalized'!$A:$A, 0))-INDEX('UZ-normalized'!$E:$E, MATCH($A2, 'UZ-normalized'!$A:$A, 0))), 0), 0))) -> -1278 | AN2: =MIN(0, N2+(IFERROR(IF(26*INDEX('UA-normalized'!$D:$D, MATCH($A2, 'UA-normalized'!$A:$A, 0))-INDEX('UA-normalized'!$E:$E, MATCH($A2, 'UA-normalized'!$A:$A, 0))>0, -(26*INDEX('UA-normalized'!$D:$D, MATCH($A2, 'UA-normalized'!$A:$A, 0))-INDEX('UA-normalized'!$E:$E, MATCH($A2, 'UA-normalized'!$A:$A, 0))), 0), 0))+(IFERROR(IF(26*INDEX('KZ-normalized'!$D:$D, MATCH($A2, 'KZ-normalized'!$A:$A, 0))-INDEX('KZ-normalized'!$E:$E, MATCH($A2, 'KZ-normalized'!$A:$A, 0))>0, -(26*INDEX('KZ-normalized'!$D:$D, MATCH($A2, 'KZ-normalized'!$A:$A, 0))-INDEX('KZ-normalized'!$E:$E, MATCH($A2, 'KZ-normalized'!$A:$A, 0))), 0), 0))+(IFERROR(IF(26*INDEX('UZ-normalized'!$D:$D, MATCH($A2, 'UZ-normalized'!$A:$A, 0))-INDEX('UZ-normalized'!$E:$E, MATCH($A2, 'UZ-normalized'!$A:$A, 0))>0, -(26*INDEX('UZ-normalized'!$D:$D, MATCH($A2, 'UZ-normalized'!$A:$A, 0))-INDEX('UZ-normalized'!$E:$E, MATCH($A2, 'UZ-normalized'!$A:$A, 0))), 0), 0))) -> -1338 | AO2: =MIN(0, N2+(IFERROR(IF(27*INDEX('UA-normalized'!$D:$D, MATCH($A2, 'UA-normalized'!$A:$A, 0))-INDEX('UA-normalized'!$E:$E, MATCH($A2, 'UA-normalized'!$A:$A, 0))>0, -(27*INDEX('UA-normalized'!$D:$D, MATCH($A2, 'UA-normalized'!$A:$A, 0))-INDEX('UA-normalized'!$E:$E, MATCH($A2, 'UA-normalized'!$A:$A, 0))), 0), 0))+(IFERROR(IF(27*INDEX('KZ-normalized'!$D:$D, MATCH($A2, 'KZ-normalized'!$A:$A, 0))-INDEX('KZ-normalized'!$E:$E, MATCH($A2, 'KZ-normalized'!$A:$A, 0))>0, -(27*INDEX('KZ-normalized'!$D:$D, MATCH($A2, 'KZ-normalized'!$A:$A, 0))-INDEX('KZ-normalized'!$E:$E, MATCH($A2, 'KZ-normalized'!$A:$A, 0))), 0), 0))+(IFERROR(IF(27*INDEX('UZ-normalized'!$D:$D, MATCH($A2, 'UZ-normalized'!$A:$A, 0))-INDEX('UZ-normalized'!$E:$E, MATCH($A2, 'UZ-normalized'!$A:$A, 0))>0, -(27*INDEX('UZ-normalized'!$D:$D, MATCH($A2, 'UZ-normalized'!$A:$A, 0))-INDEX('UZ-normalized'!$E:$E, MATCH($A2, 'UZ-normalized'!$A:$A, 0))), 0), 0))) -> -1398 | AP2: =MIN(0, N2+(IFERROR(IF(28*INDEX('UA-normalized'!$D:$D, MATCH($A2, 'UA-normalized'!$A:$A, 0))-INDEX('UA-normalized'!$E:$E, MATCH($A2, 'UA-normalized'!$A:$A, 0))>0, -(28*INDEX('UA-normalized'!$D:$D, MATCH($A2, 'UA-normalized'!$A:$A, 0))-INDEX('UA-normalized'!$E:$E, MATCH($A2, 'UA-normalized'!$A:$A, 0))), 0), 0))+(IFERROR(IF(28*INDEX('KZ-normalized'!$D:$D, MATCH($A2, 'KZ-normalized'!$A:$A, 0))-INDEX('KZ-normalized'!$E:$E, MATCH($A2, 'KZ-normalized'!$A:$A, 0))>0, -(28*INDEX('KZ-normalized'!$D:$D, MATCH($A2, 'KZ-normalized'!$A:$A, 0))-INDEX('KZ-normalized'!$E:$E, MATCH($A2, 'KZ-normalized'!$A:$A, 0))), 0), 0))+(IFERROR(IF(28*INDEX('UZ-normalized'!$D:$D, MATCH($A2, 'UZ-normalized'!$A:$A, 0))-INDEX('UZ-normalized'!$E:$E, MATCH($A2, 'UZ-normalized'!$A:$A, 0))>0, -(28*INDEX('UZ-normalized'!$D:$D, MATCH($A2, 'UZ-normalized'!$A:$A, 0))-INDEX('UZ-normalized'!$E:$E, MATCH($A2, 'UZ-normalized'!$A:$A, 0))), 0), 0))) -> -1458 | AQ2: =MIN(0, N2+(IFERROR(IF(29*INDEX('UA-normalized'!$D:$D, MATCH($A2, 'UA-normalized'!$A:$A, 0))-INDEX('UA-normalized'!$E:$E, MATCH($A2, 'UA-normalized'!$A:$A, 0))>0, -(29*INDEX('UA-normalized'!$D:$D, MATCH($A2, 'UA-normalized'!$A:$A, 0))-INDEX('UA-normalized'!$E:$E, MATCH($A2, 'UA-normalized'!$A:$A, 0))), 0), 0))+(IFERROR(IF(29*INDEX('KZ-normalized'!$D:$D, MATCH($A2, 'KZ-normalized'!$A:$A, 0))-INDEX('KZ-normalized'!$E:$E, MATCH($A2, 'KZ-normalized'!$A:$A, 0))>0, -(29*INDEX('KZ-normalized'!$D:$D, MATCH($A2, 'KZ-normalized'!$A:$A, 0))-INDEX('KZ-normalized'!$E:$E, MATCH($A2, 'KZ-normalized'!$A:$A, 0))), 0), 0))+(IFERROR(IF(29*INDEX('UZ-normalized'!$D:$D, MATCH($A2, 'UZ-normalized'!$A:$A, 0))-INDEX('UZ-normalized'!$E:$E, MATCH($A2, 'UZ-normalized'!$A:$A, 0))>0, -(29*INDEX('UZ-normalized'!$D:$D, MATCH($A2, 'UZ-normalized'!$A:$A, 0))-INDEX('UZ-normalized'!$E:$E, MATCH($A2, 'UZ-normalized'!$A:$A, 0))), 0), 0))) -> -1518 | AR2: =MIN(0, N2+(IFERROR(IF(30*INDEX('UA-normalized'!$D:$D, MATCH($A2, 'UA-normalized'!$A:$A, 0))-INDEX('UA-normalized'!$E:$E, MATCH($A2, 'UA-normalized'!$A:$A, 0))>0, -(30*INDEX('UA-normalized'!$D:$D, MATCH($A2, 'UA-normalized'!$A:$A, 0))-INDEX('UA-normalized'!$E:$E, MATCH($A2, 'UA-normalized'!$A:$A, 0))), 0), 0))+(IFERROR(IF(30*INDEX('KZ-normalized'!$D:$D, MATCH($A2, 'KZ-normalized'!$A:$A, 0))-INDEX('KZ-normalized'!$E:$E, MATCH($A2, 'KZ-normalized'!$A:$A, 0))>0, -(30*INDEX('KZ-normalized'!$D:$D, MATCH($A2, 'KZ-normalized'!$A:$A, 0))-INDEX('KZ-normalized'!$E:$E, MATCH($A2, 'KZ-normalized'!$A:$A, 0))), 0), 0))+(IFERROR(IF(30*INDEX('UZ-normalized'!$D:$D, MATCH($A2, 'UZ-normalized'!$A:$A, 0))-INDEX('UZ-normalized'!$E:$E, MATCH($A2, 'UZ-normalized'!$A:$A, 0))>0, -(30*INDEX('UZ-normalized'!$D:$D, MATCH($A2, 'UZ-normalized'!$A:$A, 0))-INDEX('UZ-normalized'!$E:$E, MATCH($A2, 'UZ-normalized'!$A:$A, 0))), 0), 0))) -> -1578
A3: PR-CHE-49-1405-025-SET | B3: CHE | C3: 1405 | D3: 19-1405-025 | N3: =SUM(E3:M3) -> 0 | O3: =MIN(0, N3+(IFERROR(IF(1*INDEX('UA-normalized'!$D:$D, MATCH($A3, 'UA-normalized'!$A:$A, 0))-INDEX('UA-normalized'!$E:$E, MATCH($A3, 'UA-normalized'!$A:$A, 0))>0, -(1*INDEX('UA-normalized'!$D:$D, MATCH($A3, 'UA-normalized'!$A:$A, 0))-INDEX('UA-normalized'!$E:$E, MATCH($A3, 'UA-normalized'!$A:$A, 0))), 0), 0))+(IFERROR(IF(1*INDEX('KZ-normalized'!$D:$D, MATCH($A3, 'KZ-normalized'!$A:$A, 0))-INDEX('KZ-normalized'!$E:$E, MATCH($A3, 'KZ-normalized'!$A:$A, 0))>0, -(1*INDEX('KZ-normalized'!$D:$D, MATCH($A3, 'KZ-normalized'!$A:$A, 0))-INDEX('KZ-normalized'!$E:$E, MATCH($A3, 'KZ-normalized'!$A:$A, 0))), 0), 0))+(IFERROR(IF(1*INDEX('UZ-normalized'!$D:$D, MATCH($A3, 'UZ-normalized'!$A:$A, 0))-INDEX('UZ-normalized'!$E:$E, MATCH($A3, 'UZ-normalized'!$A:$A, 0))>0, -(1*INDEX('UZ-normalized'!$D:$D, MATCH($A3, 'UZ-normalized'!$A:$A, 0))-INDEX('UZ-normalized'!$E:$E, MATCH($A3, 'UZ-normalized'!$A:$A, 0))), 0), 0))) -> 0 | P3: =MIN(0, N3+(IFERROR(IF(2*INDEX('UA-normalized'!$D:$D, MATCH($A3, 'UA-normalized'!$A:$A, 0))-INDEX('UA-normalized'!$E:$E, MATCH($A3, 'UA-normalized'!$A:$A, 0))>0, -(2*INDEX('UA-normalized'!$D:$D, MATCH($A3, 'UA-normalized'!$A:$A, 0))-INDEX('UA-normalized'!$E:$E, MATCH($A3, 'UA-normalized'!$A:$A, 0))), 0), 0))+(IFERROR(IF(2*INDEX('KZ-normalized'!$D:$D, MATCH($A3, 'KZ-normalized'!$A:$A, 0))-INDEX('KZ-normalized'!$E:$E, MATCH($A3, 'KZ-normalized'!$A:$A, 0))>0, -(2*INDEX('KZ-normalized'!$D:$D, MATCH($A3, 'KZ-normalized'!$A:$A, 0))-INDEX('KZ-normalized'!$E:$E, MATCH($A3, 'KZ-normalized'!$A:$A, 0))), 0), 0))+(IFERROR(IF(2*INDEX('UZ-normalized'!$D:$D, MATCH($A3, 'UZ-normalized'!$A:$A, 0))-INDEX('UZ-normalized'!$E:$E, MATCH($A3, 'UZ-normalized'!$A:$A, 0))>0, -(2*INDEX('UZ-normalized'!$D:$D, MATCH($A3, 'UZ-normalized'!$A:$A, 0))-INDEX('UZ-normalized'!$E:$E, MATCH($A3, 'UZ-normalized'!$A:$A, 0))), 0), 0))) -> 0 | Q3: =MIN(0, N3+(IFERROR(IF(3*INDEX('UA-normalized'!$D:$D, MATCH($A3, 'UA-normalized'!$A:$A, 0))-INDEX('UA-normalized'!$E:$E, MATCH($A3, 'UA-normalized'!$A:$A, 0))>0, -(3*INDEX('UA-normalized'!$D:$D, MATCH($A3, 'UA-normalized'!$A:$A, 0))-INDEX('UA-normalized'!$E:$E, MATCH($A3, 'UA-normalized'!$A:$A, 0))), 0), 0))+(IFERROR(IF(3*INDEX('KZ-normalized'!$D:$D, MATCH($A3, 'KZ-normalized'!$A:$A, 0))-INDEX('KZ-normalized'!$E:$E, MATCH($A3, 'KZ-normalized'!$A:$A, 0))>0, -(3*INDEX('KZ-normalized'!$D:$D, MATCH($A3, 'KZ-normalized'!$A:$A, 0))-INDEX('KZ-normalized'!$E:$E, MATCH($A3, 'KZ-normalized'!$A:$A, 0))), 0), 0))+(IFERROR(IF(3*INDEX('UZ-normalized'!$D:$D, MATCH($A3, 'UZ-normalized'!$A:$A, 0))-INDEX('UZ-normalized'!$E:$E, MATCH($A3, 'UZ-normalized'!$A:$A, 0))>0, -(3*INDEX('UZ-normalized'!$D:$D, MATCH($A3, 'UZ-normalized'!$A:$A, 0))-INDEX('UZ-normalized'!$E:$E, MATCH($A3, 'UZ-normalized'!$A:$A, 0))), 0), 0))) -> 0 | R3: =MIN(0, N3+(IFERROR(IF(4*INDEX('UA-normalized'!$D:$D, MATCH($A3, 'UA-normalized'!$A:$A, 0))-INDEX('UA-normalized'!$E:$E, MATCH($A3, 'UA-normalized'!$A:$A, 0))>0, -(4*INDEX('UA-normalized'!$D:$D, MATCH($A3, 'UA-normalized'!$A:$A, 0))-INDEX('UA-normalized'!$E:$E, MATCH($A3, 'UA-normalized'!$A:$A, 0))), 0), 0))+(IFERROR(IF(4*INDEX('KZ-normalized'!$D:$D, MATCH($A3, 'KZ-normalized'!$A:$A, 0))-INDEX('KZ-normalized'!$E:$E, MATCH($A3, 'KZ-normalized'!$A:$A, 0))>0, -(4*INDEX('KZ-normalized'!$D:$D, MATCH($A3, 'KZ-normalized'!$A:$A, 0))-INDEX('KZ-normalized'!$E:$E, MATCH($A3, 'KZ-normalized'!$A:$A, 0))), 0), 0))+(IFERROR(IF(4*INDEX('UZ-normalized'!$D:$D, MATCH($A3, 'UZ-normalized'!$A:$A, 0))-INDEX('UZ-normalized'!$E:$E, MATCH($A3, 'UZ-normalized'!$A:$A, 0))>0, -(4*INDEX('UZ-normalized'!$D:$D, MATCH($A3, 'UZ-normalized'!$A:$A, 0))-INDEX('UZ-normalized'!$E:$E, MATCH($A3, 'UZ-normalized'!$A:$A, 0))), 0), 0))) -> 0 | S3: =MIN(0, N3+(IFERROR(IF(5*INDEX('UA-normalized'!$D:$D, MATCH($A3, 'UA-normalized'!$A:$A, 0))-INDEX('UA-normalized'!$E:$E, MATCH($A3, 'UA-normalized'!$A:$A, 0))>0, -(5*INDEX('UA-normalized'!$D:$D, MATCH($A3, 'UA-normalized'!$A:$A, 0))-INDEX('UA-normalized'!$E:$E, MATCH($A3, 'UA-normalized'!$A:$A, 0))), 0), 0))+(IFERROR(IF(5*INDEX('KZ-normalized'!$D:$D, MATCH($A3, 'KZ-normalized'!$A:$A, 0))-INDEX('KZ-normalized'!$E:$E, MATCH($A3, 'KZ-normalized'!$A:$A, 0))>0, -(5*INDEX('KZ-normalized'!$D:$D, MATCH($A3, 'KZ-normalized'!$A:$A, 0))-INDEX('KZ-normalized'!$E:$E, MATCH($A3, 'KZ-normalized'!$A:$A, 0))), 0), 0))+(IFERROR(IF(5*INDEX('UZ-normalized'!$D:$D, MATCH($A3, 'UZ-normalized'!$A:$A, 0))-INDEX('UZ-normalized'!$E:$E, MATCH($A3, 'UZ-normalized'!$A:$A, 0))>0, -(5*INDEX('UZ-normalized'!$D:$D, MATCH($A3, 'UZ-normalized'!$A:$A, 0))-INDEX('UZ-normalized'!$E:$E, MATCH($A3, 'UZ-normalized'!$A:$A, 0))), 0), 0))) -> 0 | T3: =MIN(0, N3+(IFERROR(IF(6*INDEX('UA-normalized'!$D:$D, MATCH($A3, 'UA-normalized'!$A:$A, 0))-INDEX('UA-normalized'!$E:$E, MATCH($A3, 'UA-normalized'!$A:$A, 0))>0, -(6*INDEX('UA-normalized'!$D:$D, MATCH($A3, 'UA-normalized'!$A:$A, 0))-INDEX('UA-normalized'!$E:$E, MATCH($A3, 'UA-normalized'!$A:$A, 0))), 0), 0))+(IFERROR(IF(6*INDEX('KZ-normalized'!$D:$D, MATCH($A3, 'KZ-normalized'!$A:$A, 0))-INDEX('KZ-normalized'!$E:$E, MATCH($A3, 'KZ-normalized'!$A:$A, 0))>0, -(6*INDEX('KZ-normalized'!$D:$D, MATCH($A3, 'KZ-normalized'!$A:$A, 0))-INDEX('KZ-normalized'!$E:$E, MATCH($A3, 'KZ-normalized'!$A:$A, 0))), 0), 0))+(IFERROR(IF(6*INDEX('UZ-normalized'!$D:$D, MATCH($A3, 'UZ-normalized'!$A:$A, 0))-INDEX('UZ-normalized'!$E:$E, MATCH($A3, 'UZ-normalized'!$A:$A, 0))>0, -(6*INDEX('UZ-normalized'!$D:$D, MATCH($A3, 'UZ-normalized'!$A:$A, 0))-INDEX('UZ-normalized'!$E:$E, MATCH($A3, 'UZ-normalized'!$A:$A, 0))), 0), 0))) -> -4 | U3: =MIN(0, N3+(IFERROR(IF(7*INDEX('UA-normalized'!$D:$D, MATCH($A3, 'UA-normalized'!$A:$A, 0))-INDEX('UA-normalized'!$E:$E, MATCH($A3, 'UA-normalized'!$A:$A, 0))>0, -(7*INDEX('UA-normalized'!$D:$D, MATCH($A3, 'UA-normalized'!$A:$A, 0))-INDEX('UA-normalized'!$E:$E, MATCH($A3, 'UA-normalized'!$A:$A, 0))), 0), 0))+(IFERROR(IF(7*INDEX('KZ-normalized'!$D:$D, MATCH($A3, 'KZ-normalized'!$A:$A, 0))-INDEX('KZ-normalized'!$E:$E, MATCH($A3, 'KZ-normalized'!$A:$A, 0))>0, -(7*INDEX('KZ-normalized'!$D:$D, MATCH($A3, 'KZ-normalized'!$A:$A, 0))-INDEX('KZ-normalized'!$E:$E, MATCH($A3, 'KZ-normalized'!$A:$A, 0))), 0), 0))+(IFERROR(IF(7*INDEX('UZ-normalized'!$D:$D, MATCH($A3, 'UZ-normalized'!$A:$A, 0))-INDEX('UZ-normalized'!$E:$E, MATCH($A3, 'UZ-normalized'!$A:$A, 0))>0, -(7*INDEX('UZ-normalized'!$D:$D, MATCH($A3, 'UZ-normalized'!$A:$A, 0))-INDEX('UZ-normalized'!$E:$E, MATCH($A3, 'UZ-normalized'!$A:$A, 0))), 0), 0))) -> -18 | V3: =MIN(0, N3+(IFERROR(IF(8*INDEX('UA-normalized'!$D:$D, MATCH($A3, 'UA-normalized'!$A:$A, 0))-INDEX('UA-normalized'!$E:$E, MATCH($A3, 'UA-normalized'!$A:$A, 0))>0, -(8*INDEX('UA-normalized'!$D:$D, MATCH($A3, 'UA-normalized'!$A:$A, 0))-INDEX('UA-normalized'!$E:$E, MATCH($A3, 'UA-normalized'!$A:$A, 0))), 0), 0))+(IFERROR(IF(8*INDEX('KZ-normalized'!$D:$D, MATCH($A3, 'KZ-normalized'!$A:$A, 0))-INDEX('KZ-normalized'!$E:$E, MATCH($A3, 'KZ-normalized'!$A:$A, 0))>0, -(8*INDEX('KZ-normalized'!$D:$D, MATCH($A3, 'KZ-normalized'!$A:$A, 0))-INDEX('KZ-normalized'!$E:$E, MATCH($A3, 'KZ-normalized'!$A:$A, 0))), 0), 0))+(IFERROR(IF(8*INDEX('UZ-normalized'!$D:$D, MATCH($A3, 'UZ-normalized'!$A:$A, 0))-INDEX('UZ-normalized'!$E:$E, MATCH($A3, 'UZ-normalized'!$A:$A, 0))>0, -(8*INDEX('UZ-normalized'!$D:$D, MATCH($A3, 'UZ-normalized'!$A:$A, 0))-INDEX('UZ-normalized'!$E:$E, MATCH($A3, 'UZ-normalized'!$A:$A, 0))), 0), 0))) -> -32 | W3: =MIN(0, N3+(IFERROR(IF(9*INDEX('UA-normalized'!$D:$D, MATCH($A3, 'UA-normalized'!$A:$A, 0))-INDEX('UA-normalized'!$E:$E, MATCH($A3, 'UA-normalized'!$A:$A, 0))>0, -(9*INDEX('UA-normalized'!$D:$D, MATCH($A3, 'UA-normalized'!$A:$A, 0))-INDEX('UA-normalized'!$E:$E, MATCH($A3, 'UA-normalized'!$A:$A, 0))), 0), 0))+(IFERROR(IF(9*INDEX('KZ-normalized'!$D:$D, MATCH($A3, 'KZ-normalized'!$A:$A, 0))-INDEX('KZ-normalized'!$E:$E, MATCH($A3, 'KZ-normalized'!$A:$A, 0))>0, -(9*INDEX('KZ-normalized'!$D:$D, MATCH($A3, 'KZ-normalized'!$A:$A, 0))-INDEX('KZ-normalized'!$E:$E, MATCH($A3, 'KZ-normalized'!$A:$A, 0))), 0), 0))+(IFERROR(IF(9*INDEX('UZ-normalized'!$D:$D, MATCH($A3, 'UZ-normalized'!$A:$A, 0))-INDEX('UZ-normalized'!$E:$E, MATCH($A3, 'UZ-normalized'!$A:$A, 0))>0, -(9*INDEX('UZ-normalized'!$D:$D, MATCH($A3, 'UZ-normalized'!$A:$A, 0))-INDEX('UZ-normalized'!$E:$E, MATCH($A3, 'UZ-normalized'!$A:$A, 0))), 0), 0))) -> -46 | X3: =MIN(0, N3+(IFERROR(IF(10*INDEX('UA-normalized'!$D:$D, MATCH($A3, 'UA-normalized'!$A:$A, 0))-INDEX('UA-normalized'!$E:$E, MATCH($A3, 'UA-normalized'!$A:$A, 0))>0, -(10*INDEX('UA-normalized'!$D:$D, MATCH($A3, 'UA-normalized'!$A:$A, 0))-INDEX('UA-normalized'!$E:$E, MATCH($A3, 'UA-normalized'!$A:$A, 0))), 0), 0))+(IFERROR(IF(10*INDEX('KZ-normalized'!$D:$D, MATCH($A3, 'KZ-normalized'!$A:$A, 0))-INDEX('KZ-normalized'!$E:$E, MATCH($A3, 'KZ-normalized'!$A:$A, 0))>0, -(10*INDEX('KZ-normalized'!$D:$D, MATCH($A3, 'KZ-normalized'!$A:$A, 0))-INDEX('KZ-normalized'!$E:$E, MATCH($A3, 'KZ-normalized'!$A:$A, 0))), 0), 0))+(IFERROR(IF(10*INDEX('UZ-normalized'!$D:$D, MATCH($A3, 'UZ-normalized'!$A:$A, 0))-INDEX('UZ-normalized'!$E:$E, MATCH($A3, 'UZ-normalized'!$A:$A, 0))>0, -(10*INDEX('UZ-normalized'!$D:$D, MATCH($A3, 'UZ-normalized'!$A:$A, 0))-INDEX('UZ-normalized'!$E:$E, MATCH($A3, 'UZ-normalized'!$A:$A, 0))), 0), 0))) -> -60 | Y3: =MIN(0, N3+(IFERROR(IF(11*INDEX('UA-normalized'!$D:$D, MATCH($A3, 'UA-normalized'!$A:$A, 0))-INDEX('UA-normalized'!$E:$E, MATCH($A3, 'UA-normalized'!$A:$A, 0))>0, -(11*INDEX('UA-normalized'!$D:$D, MATCH($A3, 'UA-normalized'!$A:$A, 0))-INDEX('UA-normalized'!$E:$E, MATCH($A3, 'UA-normalized'!$A:$A, 0))), 0), 0))+(IFERROR(IF(11*INDEX('KZ-normalized'!$D:$D, MATCH($A3, 'KZ-normalized'!$A:$A, 0))-INDEX('KZ-normalized'!$E:$E, MATCH($A3, 'KZ-normalized'!$A:$A, 0))>0, -(11*INDEX('KZ-normalized'!$D:$D, MATCH($A3, 'KZ-normalized'!$A:$A, 0))-INDEX('KZ-normalized'!$E:$E, MATCH($A3, 'KZ-normalized'!$A:$A, 0))), 0), 0))+(IFERROR(IF(11*INDEX('UZ-normalized'!$D:$D, MATCH($A3, 'UZ-normalized'!$A:$A, 0))-INDEX('UZ-normalized'!$E:$E, MATCH($A3, 'UZ-normalized'!$A:$A, 0))>0, -(11*INDEX('UZ-normalized'!$D:$D, MATCH($A3, 'UZ-normalized'!$A:$A, 0))-INDEX('UZ-normalized'!$E:$E, MATCH($A3, 'UZ-normalized'!$A:$A, 0))), 0), 0))) -> -74 | Z3: =MIN(0, N3+(IFERROR(IF(12*INDEX('UA-normalized'!$D:$D, MATCH($A3, 'UA-normalized'!$A:$A, 0))-INDEX('UA-normalized'!$E:$E, MATCH($A3, 'UA-normalized'!$A:$A, 0))>0, -(12*INDEX('UA-normalized'!$D:$D, MATCH($A3, 'UA-normalized'!$A:$A, 0))-INDEX('UA-normalized'!$E:$E, MATCH($A3, 'UA-normalized'!$A:$A, 0))), 0), 0))+(IFERROR(IF(12*INDEX('KZ-normalized'!$D:$D, MATCH($A3, 'KZ-normalized'!$A:$A, 0))-INDEX('KZ-normalized'!$E:$E, MATCH($A3, 'KZ-normalized'!$A:$A, 0))>0, -(12*INDEX('KZ-normalized'!$D:$D, MATCH($A3, 'KZ-normalized'!$A:$A, 0))-INDEX('KZ-normalized'!$E:$E, MATCH($A3, 'KZ-normalized'!$A:$A, 0))), 0), 0))+(IFERROR(IF(12*INDEX('UZ-normalized'!$D:$D, MATCH($A3, 'UZ-normalized'!$A:$A, 0))-INDEX('UZ-normalized'!$E:$E, MATCH($A3, 'UZ-normalized'!$A:$A, 0))>0, -(12*INDEX('UZ-normalized'!$D:$D, MATCH($A3, 'UZ-normalized'!$A:$A, 0))-INDEX('UZ-normalized'!$E:$E, MATCH($A3, 'UZ-normalized'!$A:$A, 0))), 0), 0))) -> -88 | AA3: =MIN(0, N3+(IFERROR(IF(13*INDEX('UA-normalized'!$D:$D, MATCH($A3, 'UA-normalized'!$A:$A, 0))-INDEX('UA-normalized'!$E:$E, MATCH($A3, 'UA-normalized'!$A:$A, 0))>0, -(13*INDEX('UA-normalized'!$D:$D, MATCH($A3, 'UA-normalized'!$A:$A, 0))-INDEX('UA-normalized'!$E:$E, MATCH($A3, 'UA-normalized'!$A:$A, 0))), 0), 0))+(IFERROR(IF(13*INDEX('KZ-normalized'!$D:$D, MATCH($A3, 'KZ-normalized'!$A:$A, 0))-INDEX('KZ-normalized'!$E:$E, MATCH($A3, 'KZ-normalized'!$A:$A, 0))>0, -(13*INDEX('KZ-normalized'!$D:$D, MATCH($A3, 'KZ-normalized'!$A:$A, 0))-INDEX('KZ-normalized'!$E:$E, MATCH($A3, 'KZ-normalized'!$A:$A, 0))), 0), 0))+(IFERROR(IF(13*INDEX('UZ-normalized'!$D:$D, MATCH($A3, 'UZ-normalized'!$A:$A, 0))-INDEX('UZ-normalized'!$E:$E, MATCH($A3, 'UZ-normalized'!$A:$A, 0))>0, -(13*INDEX('UZ-normalized'!$D:$D, MATCH($A3, 'UZ-normalized'!$A:$A, 0))-INDEX('UZ-normalized'!$E:$E, MATCH($A3, 'UZ-normalized'!$A:$A, 0))), 0), 0))) -> -102 | AB3: =MIN(0, N3+(IFERROR(IF(14*INDEX('UA-normalized'!$D:$D, MATCH($A3, 'UA-normalized'!$A:$A, 0))-INDEX('UA-normalized'!$E:$E, MATCH($A3, 'UA-normalized'!$A:$A, 0))>0, -(14*INDEX('UA-normalized'!$D:$D, MATCH($A3, 'UA-normalized'!$A:$A, 0))-INDEX('UA-normalized'!$E:$E, MATCH($A3, 'UA-normalized'!$A:$A, 0))), 0), 0))+(IFERROR(IF(14*INDEX('KZ-normalized'!$D:$D, MATCH($A3, 'KZ-normalized'!$A:$A, 0))-INDEX('KZ-normalized'!$E:$E, MATCH($A3, 'KZ-normalized'!$A:$A, 0))>0, -(14*INDEX('KZ-normalized'!$D:$D, MATCH($A3, 'KZ-normalized'!$A:$A, 0))-INDEX('KZ-normalized'!$E:$E, MATCH($A3, 'KZ-normalized'!$A:$A, 0))), 0), 0))+(IFERROR(IF(14*INDEX('UZ-normalized'!$D:$D, MATCH($A3, 'UZ-normalized'!$A:$A, 0))-INDEX('UZ-normalized'!$E:$E, MATCH($A3, 'UZ-normalized'!$A:$A, 0))>0, -(14*INDEX('UZ-normalized'!$D:$D, MATCH($A3, 'UZ-normalized'!$A:$A, 0))-INDEX('UZ-normalized'!$E:$E, MATCH($A3, 'UZ-normalized'!$A:$A, 0))), 0), 0))) -> -116 | AC3: =MIN(0, N3+(IFERROR(IF(15*INDEX('UA-normalized'!$D:$D, MATCH($A3, 'UA-normalized'!$A:$A, 0))-INDEX('UA-normalized'!$E:$E, MATCH($A3, 'UA-normalized'!$A:$A, 0))>0, -(15*INDEX('UA-normalized'!$D:$D, MATCH($A3, 'UA-normalized'!$A:$A, 0))-INDEX('UA-normalized'!$E:$E, MATCH($A3, 'UA-normalized'!$A:$A, 0))), 0), 0))+(IFERROR(IF(15*INDEX('KZ-normalized'!$D:$D, MATCH($A3, 'KZ-normalized'!$A:$A, 0))-INDEX('KZ-normalized'!$E:$E, MATCH($A3, 'KZ-normalized'!$A:$A, 0))>0, -(15*INDEX('KZ-normalized'!$D:$D, MATCH($A3, 'KZ-normalized'!$A:$A, 0))-INDEX('KZ-normalized'!$E:$E, MATCH($A3, 'KZ-normalized'!$A:$A, 0))), 0), 0))+(IFERROR(IF(15*INDEX('UZ-normalized'!$D:$D, MATCH($A3, 'UZ-normalized'!$A:$A, 0))-INDEX('UZ-normalized'!$E:$E, MATCH($A3, 'UZ-normalized'!$A:$A, 0))>0, -(15*INDEX('UZ-normalized'!$D:$D, MATCH($A3, 'UZ-normalized'!$A:$A, 0))-INDEX('UZ-normalized'!$E:$E, MATCH($A3, 'UZ-normalized'!$A:$A, 0))), 0), 0))) -> -130 | AD3: =MIN(0, N3+(IFERROR(IF(16*INDEX('UA-normalized'!$D:$D, MATCH($A3, 'UA-normalized'!$A:$A, 0))-INDEX('UA-normalized'!$E:$E, MATCH($A3, 'UA-normalized'!$A:$A, 0))>0, -(16*INDEX('UA-normalized'!$D:$D, MATCH($A3, 'UA-normalized'!$A:$A, 0))-INDEX('UA-normalized'!$E:$E, MATCH($A3, 'UA-normalized'!$A:$A, 0))), 0), 0))+(IFERROR(IF(16*INDEX('KZ-normalized'!$D:$D, MATCH($A3, 'KZ-normalized'!$A:$A, 0))-INDEX('KZ-normalized'!$E:$E, MATCH($A3, 'KZ-normalized'!$A:$A, 0))>0, -(16*INDEX('KZ-normalized'!$D:$D, MATCH($A3, 'KZ-normalized'!$A:$A, 0))-INDEX('KZ-normalized'!$E:$E, MATCH($A3, 'KZ-normalized'!$A:$A, 0))), 0), 0))+(IFERROR(IF(16*INDEX('UZ-normalized'!$D:$D, MATCH($A3, 'UZ-normalized'!$A:$A, 0))-INDEX('UZ-normalized'!$E:$E, MATCH($A3, 'UZ-normalized'!$A:$A, 0))>0, -(16*INDEX('UZ-normalized'!$D:$D, MATCH($A3, 'UZ-normalized'!$A:$A, 0))-INDEX('UZ-normalized'!$E:$E, MATCH($A3, 'UZ-normalized'!$A:$A, 0))), 0), 0))) -> -144 | AE3: =MIN(0, N3+(IFERROR(IF(17*INDEX('UA-normalized'!$D:$D, MATCH($A3, 'UA-normalized'!$A:$A, 0))-INDEX('UA-normalized'!$E:$E, MATCH($A3, 'UA-normalized'!$A:$A, 0))>0, -(17*INDEX('UA-normalized'!$D:$D, MATCH($A3, 'UA-normalized'!$A:$A, 0))-INDEX('UA-normalized'!$E:$E, MATCH($A3, 'UA-normalized'!$A:$A, 0))), 0), 0))+(IFERROR(IF(17*INDEX('KZ-normalized'!$D:$D, MATCH($A3, 'KZ-normalized'!$A:$A, 0))-INDEX('KZ-normalized'!$E:$E, MATCH($A3, 'KZ-normalized'!$A:$A, 0))>0, -(17*INDEX('KZ-normalized'!$D:$D, MATCH($A3, 'KZ-normalized'!$A:$A, 0))-INDEX('KZ-normalized'!$E:$E, MATCH($A3, 'KZ-normalized'!$A:$A, 0))), 0), 0))+(IFERROR(IF(17*INDEX('UZ-normalized'!$D:$D, MATCH($A3, 'UZ-normalized'!$A:$A, 0))-INDEX('UZ-normalized'!$E:$E, MATCH($A3, 'UZ-normalized'!$A:$A, 0))>0, -(17*INDEX('UZ-normalized'!$D:$D, MATCH($A3, 'UZ-normalized'!$A:$A, 0))-INDEX('UZ-normalized'!$E:$E, MATCH($A3, 'UZ-normalized'!$A:$A, 0))), 0), 0))) -> -158 | AF3: =MIN(0, N3+(IFERROR(IF(18*INDEX('UA-normalized'!$D:$D, MATCH($A3, 'UA-normalized'!$A:$A, 0))-INDEX('UA-normalized'!$E:$E, MATCH($A3, 'UA-normalized'!$A:$A, 0))>0, -(18*INDEX('UA-normalized'!$D:$D, MATCH($A3, 'UA-normalized'!$A:$A, 0))-INDEX('UA-normalized'!$E:$E, MATCH($A3, 'UA-normalized'!$A:$A, 0))), 0), 0))+(IFERROR(IF(18*INDEX('KZ-normalized'!$D:$D, MATCH($A3, 'KZ-normalized'!$A:$A, 0))-INDEX('KZ-normalized'!$E:$E, MATCH($A3, 'KZ-normalized'!$A:$A, 0))>0, -(18*INDEX('KZ-normalized'!$D:$D, MATCH($A3, 'KZ-normalized'!$A:$A, 0))-INDEX('KZ-normalized'!$E:$E, MATCH($A3, 'KZ-normalized'!$A:$A, 0))), 0), 0))+(IFERROR(IF(18*INDEX('UZ-normalized'!$D:$D, MATCH($A3, 'UZ-normalized'!$A:$A, 0))-INDEX('UZ-normalized'!$E:$E, MATCH($A3, 'UZ-normalized'!$A:$A, 0))>0, -(18*INDEX('UZ-normalized'!$D:$D, MATCH($A3, 'UZ-normalized'!$A:$A, 0))-INDEX('UZ-normalized'!$E:$E, MATCH($A3, 'UZ-normalized'!$A:$A, 0))), 0), 0))) -> -172 | AG3: =MIN(0, N3+(IFERROR(IF(19*INDEX('UA-normalized'!$D:$D, MATCH($A3, 'UA-normalized'!$A:$A, 0))-INDEX('UA-normalized'!$E:$E, MATCH($A3, 'UA-normalized'!$A:$A, 0))>0, -(19*INDEX('UA-normalized'!$D:$D, MATCH($A3, 'UA-normalized'!$A:$A, 0))-INDEX('UA-normalized'!$E:$E, MATCH($A3, 'UA-normalized'!$A:$A, 0))), 0), 0))+(IFERROR(IF(19*INDEX('KZ-normalized'!$D:$D, MATCH($A3, 'KZ-normalized'!$A:$A, 0))-INDEX('KZ-normalized'!$E:$E, MATCH($A3, 'KZ-normalized'!$A:$A, 0))>0, -(19*INDEX('KZ-normalized'!$D:$D, MATCH($A3, 'KZ-normalized'!$A:$A, 0))-INDEX('KZ-normalized'!$E:$E, MATCH($A3, 'KZ-normalized'!$A:$A, 0))), 0), 0))+(IFERROR(IF(19*INDEX('UZ-normalized'!$D:$D, MATCH($A3, 'UZ-normalized'!$A:$A, 0))-INDEX('UZ-normalized'!$E:$E, MATCH($A3, 'UZ-normalized'!$A:$A, 0))>0, -(19*INDEX('UZ-normalized'!$D:$D, MATCH($A3, 'UZ-normalized'!$A:$A, 0))-INDEX('UZ-normalized'!$E:$E, MATCH($A3, 'UZ-normalized'!$A:$A, 0))), 0), 0))) -> -186 | AH3: =MIN(0, N3+(IFERROR(IF(20*INDEX('UA-normalized'!$D:$D, MATCH($A3, 'UA-normalized'!$A:$A, 0))-INDEX('UA-normalized'!$E:$E, MATCH($A3, 'UA-normalized'!$A:$A, 0))>0, -(20*INDEX('UA-normalized'!$D:$D, MATCH($A3, 'UA-normalized'!$A:$A, 0))-INDEX('UA-normalized'!$E:$E, MATCH($A3, 'UA-normalized'!$A:$A, 0))), 0), 0))+(IFERROR(IF(20*INDEX('KZ-normalized'!$D:$D, MATCH($A3, 'KZ-normalized'!$A:$A, 0))-INDEX('KZ-normalized'!$E:$E, MATCH($A3, 'KZ-normalized'!$A:$A, 0))>0, -(20*INDEX('KZ-normalized'!$D:$D, MATCH($A3, 'KZ-normalized'!$A:$A, 0))-INDEX('KZ-normalized'!$E:$E, MATCH($A3, 'KZ-normalized'!$A:$A, 0))), 0), 0))+(IFERROR(IF(20*INDEX('UZ-normalized'!$D:$D, MATCH($A3, 'UZ-normalized'!$A:$A, 0))-INDEX('UZ-normalized'!$E:$E, MATCH($A3, 'UZ-normalized'!$A:$A, 0))>0, -(20*INDEX('UZ-normalized'!$D:$D, MATCH($A3, 'UZ-normalized'!$A:$A, 0))-INDEX('UZ-normalized'!$E:$E, MATCH($A3, 'UZ-normalized'!$A:$A, 0))), 0), 0))) -> -200 | AI3: =MIN(0, N3+(IFERROR(IF(21*INDEX('UA-normalized'!$D:$D, MATCH($A3, 'UA-normalized'!$A:$A, 0))-INDEX('UA-normalized'!$E:$E, MATCH($A3, 'UA-normalized'!$A:$A, 0))>0, -(21*INDEX('UA-normalized'!$D:$D, MATCH($A3, 'UA-normalized'!$A:$A, 0))-INDEX('UA-normalized'!$E:$E, MATCH($A3, 'UA-normalized'!$A:$A, 0))), 0), 0))+(IFERROR(IF(21*INDEX('KZ-normalized'!$D:$D, MATCH($A3, 'KZ-normalized'!$A:$A, 0))-INDEX('KZ-normalized'!$E:$E, MATCH($A3, 'KZ-normalized'!$A:$A, 0))>0, -(21*INDEX('KZ-normalized'!$D:$D, MATCH($A3, 'KZ-normalized'!$A:$A, 0))-INDEX('KZ-normalized'!$E:$E, MATCH($A3, 'KZ-normalized'!$A:$A, 0))), 0), 0))+(IFERROR(IF(21*INDEX('UZ-normalized'!$D:$D, MATCH($A3, 'UZ-normalized'!$A:$A, 0))-INDEX('UZ-normalized'!$E:$E, MATCH($A3, 'UZ-normalized'!$A:$A, 0))>0, -(21*INDEX('UZ-normalized'!$D:$D, MATCH($A3, 'UZ-normalized'!$A:$A, 0))-INDEX('UZ-normalized'!$E:$E, MATCH($A3, 'UZ-normalized'!$A:$A, 0))), 0), 0))) -> -214 | AJ3: =MIN(0, N3+(IFERROR(IF(22*INDEX('UA-normalized'!$D:$D, MATCH($A3, 'UA-normalized'!$A:$A, 0))-INDEX('UA-normalized'!$E:$E, MATCH($A3, 'UA-normalized'!$A:$A, 0))>0, -(22*INDEX('UA-normalized'!$D:$D, MATCH($A3, 'UA-normalized'!$A:$A, 0))-INDEX('UA-normalized'!$E:$E, MATCH($A3, 'UA-normalized'!$A:$A, 0))), 0), 0))+(IFERROR(IF(22*INDEX('KZ-normalized'!$D:$D, MATCH($A3, 'KZ-normalized'!$A:$A, 0))-INDEX('KZ-normalized'!$E:$E, MATCH($A3, 'KZ-normalized'!$A:$A, 0))>0, -(22*INDEX('KZ-normalized'!$D:$D, MATCH($A3, 'KZ-normalized'!$A:$A, 0))-INDEX('KZ-normalized'!$E:$E, MATCH($A3, 'KZ-normalized'!$A:$A, 0))), 0), 0))+(IFERROR(IF(22*INDEX('UZ-normalized'!$D:$D, MATCH($A3, 'UZ-normalized'!$A:$A, 0))-INDEX('UZ-normalized'!$E:$E, MATCH($A3, 'UZ-normalized'!$A:$A, 0))>0, -(22*INDEX('UZ-normalized'!$D:$D, MATCH($A3, 'UZ-normalized'!$A:$A, 0))-INDEX('UZ-normalized'!$E:$E, MATCH($A3, 'UZ-normalized'!$A:$A, 0))), 0), 0))) -> -228 | AK3: =MIN(0, N3+(IFERROR(IF(23*INDEX('UA-normalized'!$D:$D, MATCH($A3, 'UA-normalized'!$A:$A, 0))-INDEX('UA-normalized'!$E:$E, MATCH($A3, 'UA-normalized'!$A:$A, 0))>0, -(23*INDEX('UA-normalized'!$D:$D, MATCH($A3, 'UA-normalized'!$A:$A, 0))-INDEX('UA-normalized'!$E:$E, MATCH($A3, 'UA-normalized'!$A:$A, 0))), 0), 0))+(IFERROR(IF(23*INDEX('KZ-normalized'!$D:$D, MATCH($A3, 'KZ-normalized'!$A:$A, 0))-INDEX('KZ-normalized'!$E:$E, MATCH($A3, 'KZ-normalized'!$A:$A, 0))>0, -(23*INDEX('KZ-normalized'!$D:$D, MATCH($A3, 'KZ-normalized'!$A:$A, 0))-INDEX('KZ-normalized'!$E:$E, MATCH($A3, 'KZ-normalized'!$A:$A, 0))), 0), 0))+(IFERROR(IF(23*INDEX('UZ-normalized'!$D:$D, MATCH($A3, 'UZ-normalized'!$A:$A, 0))-INDEX('UZ-normalized'!$E:$E, MATCH($A3, 'UZ-normalized'!$A:$A, 0))>0, -(23*INDEX('UZ-normalized'!$D:$D, MATCH($A3, 'UZ-normalized'!$A:$A, 0))-INDEX('UZ-normalized'!$E:$E, MATCH($A3, 'UZ-normalized'!$A:$A, 0))), 0), 0))) -> -242 | AL3: =MIN(0, N3+(IFERROR(IF(24*INDEX('UA-normalized'!$D:$D, MATCH($A3, 'UA-normalized'!$A:$A, 0))-INDEX('UA-normalized'!$E:$E, MATCH($A3, 'UA-normalized'!$A:$A, 0))>0, -(24*INDEX('UA-normalized'!$D:$D, MATCH($A3, 'UA-normalized'!$A:$A, 0))-INDEX('UA-normalized'!$E:$E, MATCH($A3, 'UA-normalized'!$A:$A, 0))), 0), 0))+(IFERROR(IF(24*INDEX('KZ-normalized'!$D:$D, MATCH($A3, 'KZ-normalized'!$A:$A, 0))-INDEX('KZ-normalized'!$E:$E, MATCH($A3, 'KZ-normalized'!$A:$A, 0))>0, -(24*INDEX('KZ-normalized'!$D:$D, MATCH($A3, 'KZ-normalized'!$A:$A, 0))-INDEX('KZ-normalized'!$E:$E, MATCH($A3, 'KZ-normalized'!$A:$A, 0))), 0), 0))+(IFERROR(IF(24*INDEX('UZ-normalized'!$D:$D, MATCH($A3, 'UZ-normalized'!$A:$A, 0))-INDEX('UZ-normalized'!$E:$E, MATCH($A3, 'UZ-normalized'!$A:$A, 0))>0, -(24*INDEX('UZ-normalized'!$D:$D, MATCH($A3, 'UZ-normalized'!$A:$A, 0))-INDEX('UZ-normalized'!$E:$E, MATCH($A3, 'UZ-normalized'!$A:$A, 0))), 0), 0))) -> -256 | AM3: =MIN(0, N3+(IFERROR(IF(25*INDEX('UA-normalized'!$D:$D, MATCH($A3, 'UA-normalized'!$A:$A, 0))-INDEX('UA-normalized'!$E:$E, MATCH($A3, 'UA-normalized'!$A:$A, 0))>0, -(25*INDEX('UA-normalized'!$D:$D, MATCH($A3, 'UA-normalized'!$A:$A, 0))-INDEX('UA-normalized'!$E:$E, MATCH($A3, 'UA-normalized'!$A:$A, 0))), 0), 0))+(IFERROR(IF(25*INDEX('KZ-normalized'!$D:$D, MATCH($A3, 'KZ-normalized'!$A:$A, 0))-INDEX('KZ-normalized'!$E:$E, MATCH($A3, 'KZ-normalized'!$A:$A, 0))>0, -(25*INDEX('KZ-normalized'!$D:$D, MATCH($A3, 'KZ-normalized'!$A:$A, 0))-INDEX('KZ-normalized'!$E:$E, MATCH($A3, 'KZ-normalized'!$A:$A, 0))), 0), 0))+(IFERROR(IF(25*INDEX('UZ-normalized'!$D:$D, MATCH($A3, 'UZ-normalized'!$A:$A, 0))-INDEX('UZ-normalized'!$E:$E, MATCH($A3, 'UZ-normalized'!$A:$A, 0))>0, -(25*INDEX('UZ-normalized'!$D:$D, MATCH($A3, 'UZ-normalized'!$A:$A, 0))-INDEX('UZ-normalized'!$E:$E, MATCH($A3, 'UZ-normalized'!$A:$A, 0))), 0), 0))) -> -270 | AN3: =MIN(0, N3+(IFERROR(IF(26*INDEX('UA-normalized'!$D:$D, MATCH($A3, 'UA-normalized'!$A:$A, 0))-INDEX('UA-normalized'!$E:$E, MATCH($A3, 'UA-normalized'!$A:$A, 0))>0, -(26*INDEX('UA-normalized'!$D:$D, MATCH($A3, 'UA-normalized'!$A:$A, 0))-INDEX('UA-normalized'!$E:$E, MATCH($A3, 'UA-normalized'!$A:$A, 0))), 0), 0))+(IFERROR(IF(26*INDEX('KZ-normalized'!$D:$D, MATCH($A3, 'KZ-normalized'!$A:$A, 0))-INDEX('KZ-normalized'!$E:$E, MATCH($A3, 'KZ-normalized'!$A:$A, 0))>0, -(26*INDEX('KZ-normalized'!$D:$D, MATCH($A3, 'KZ-normalized'!$A:$A, 0))-INDEX('KZ-normalized'!$E:$E, MATCH($A3, 'KZ-normalized'!$A:$A, 0))), 0), 0))+(IFERROR(IF(26*INDEX('UZ-normalized'!$D:$D, MATCH($A3, 'UZ-normalized'!$A:$A, 0))-INDEX('UZ-normalized'!$E:$E, MATCH($A3, 'UZ-normalized'!$A:$A, 0))>0, -(26*INDEX('UZ-normalized'!$D:$D, MATCH($A3, 'UZ-normalized'!$A:$A, 0))-INDEX('UZ-normalized'!$E:$E, MATCH($A3, 'UZ-normalized'!$A:$A, 0))), 0), 0))) -> -284 | AO3: =MIN(0, N3+(IFERROR(IF(27*INDEX('UA-normalized'!$D:$D, MATCH($A3, 'UA-normalized'!$A:$A, 0))-INDEX('UA-normalized'!$E:$E, MATCH($A3, 'UA-normalized'!$A:$A, 0))>0, -(27*INDEX('UA-normalized'!$D:$D, MATCH($A3, 'UA-normalized'!$A:$A, 0))-INDEX('UA-normalized'!$E:$E, MATCH($A3, 'UA-normalized'!$A:$A, 0))), 0), 0))+(IFERROR(IF(27*INDEX('KZ-normalized'!$D:$D, MATCH($A3, 'KZ-normalized'!$A:$A, 0))-INDEX('KZ-normalized'!$E:$E, MATCH($A3, 'KZ-normalized'!$A:$A, 0))>0, -(27*INDEX('KZ-normalized'!$D:$D, MATCH($A3, 'KZ-normalized'!$A:$A, 0))-INDEX('KZ-normalized'!$E:$E, MATCH($A3, 'KZ-normalized'!$A:$A, 0))), 0), 0))+(IFERROR(IF(27*INDEX('UZ-normalized'!$D:$D, MATCH($A3, 'UZ-normalized'!$A:$A, 0))-INDEX('UZ-normalized'!$E:$E, MATCH($A3, 'UZ-normalized'!$A:$A, 0))>0, -(27*INDEX('UZ-normalized'!$D:$D, MATCH($A3, 'UZ-normalized'!$A:$A, 0))-INDEX('UZ-normalized'!$E:$E, MATCH($A3, 'UZ-normalized'!$A:$A, 0))), 0), 0))) -> -298 | AP3: =MIN(0, N3+(IFERROR(IF(28*INDEX('UA-normalized'!$D:$D, MATCH($A3, 'UA-normalized'!$A:$A, 0))-INDEX('UA-normalized'!$E:$E, MATCH($A3, 'UA-normalized'!$A:$A, 0))>0, -(28*INDEX('UA-normalized'!$D:$D, MATCH($A3, 'UA-normalized'!$A:$A, 0))-INDEX('UA-normalized'!$E:$E, MATCH($A3, 'UA-normalized'!$A:$A, 0))), 0), 0))+(IFERROR(IF(28*INDEX('KZ-normalized'!$D:$D, MATCH($A3, 'KZ-normalized'!$A:$A, 0))-INDEX('KZ-normalized'!$E:$E, MATCH($A3, 'KZ-normalized'!$A:$A, 0))>0, -(28*INDEX('KZ-normalized'!$D:$D, MATCH($A3, 'KZ-normalized'!$A:$A, 0))-INDEX('KZ-normalized'!$E:$E, MATCH($A3, 'KZ-normalized'!$A:$A, 0))), 0), 0))+(IFERROR(IF(28*INDEX('UZ-normalized'!$D:$D, MATCH($A3, 'UZ-normalized'!$A:$A, 0))-INDEX('UZ-normalized'!$E:$E, MATCH($A3, 'UZ-normalized'!$A:$A, 0))>0, -(28*INDEX('UZ-normalized'!$D:$D, MATCH($A3, 'UZ-normalized'!$A:$A, 0))-INDEX('UZ-normalized'!$E:$E, MATCH($A3, 'UZ-normalized'!$A:$A, 0))), 0), 0))) -> -312 | AQ3: =MIN(0, N3+(IFERROR(IF(29*INDEX('UA-normalized'!$D:$D, MATCH($A3, 'UA-normalized'!$A:$A, 0))-INDEX('UA-normalized'!$E:$E, MATCH($A3, 'UA-normalized'!$A:$A, 0))>0, -(29*INDEX('UA-normalized'!$D:$D, MATCH($A3, 'UA-normalized'!$A:$A, 0))-INDEX('UA-normalized'!$E:$E, MATCH($A3, 'UA-normalized'!$A:$A, 0))), 0), 0))+(IFERROR(IF(29*INDEX('KZ-normalized'!$D:$D, MATCH($A3, 'KZ-normalized'!$A:$A, 0))-INDEX('KZ-normalized'!$E:$E, MATCH($A3, 'KZ-normalized'!$A:$A, 0))>0, -(29*INDEX('KZ-normalized'!$D:$D, MATCH($A3, 'KZ-normalized'!$A:$A, 0))-INDEX('KZ-normalized'!$E:$E, MATCH($A3, 'KZ-normalized'!$A:$A, 0))), 0), 0))+(IFERROR(IF(29*INDEX('UZ-normalized'!$D:$D, MATCH($A3, 'UZ-normalized'!$A:$A, 0))-INDEX('UZ-normalized'!$E:$E, MATCH($A3, 'UZ-normalized'!$A:$A, 0))>0, -(29*INDEX('UZ-normalized'!$D:$D, MATCH($A3, 'UZ-normalized'!$A:$A, 0))-INDEX('UZ-normalized'!$E:$E, MATCH($A3, 'UZ-normalized'!$A:$A, 0))), 0), 0))) -> -326 | AR3: =MIN(0, N3+(IFERROR(IF(30*INDEX('UA-normalized'!$D:$D, MATCH($A3, 'UA-normalized'!$A:$A, 0))-INDEX('UA-normalized'!$E:$E, MATCH($A3, 'UA-normalized'!$A:$A, 0))>0, -(30*INDEX('UA-normalized'!$D:$D, MATCH($A3, 'UA-normalized'!$A:$A, 0))-INDEX('UA-normalized'!$E:$E, MATCH($A3, 'UA-normalized'!$A:$A, 0))), 0), 0))+(IFERROR(IF(30*INDEX('KZ-normalized'!$D:$D, MATCH($A3, 'KZ-normalized'!$A:$A, 0))-INDEX('KZ-normalized'!$E:$E, MATCH($A3, 'KZ-normalized'!$A:$A, 0))>0, -(30*INDEX('KZ-normalized'!$D:$D, MATCH($A3, 'KZ-normalized'!$A:$A, 0))-INDEX('KZ-normalized'!$E:$E, MATCH($A3, 'KZ-normalized'!$A:$A, 0))), 0), 0))+(IFERROR(IF(30*INDEX('UZ-normalized'!$D:$D, MATCH($A3, 'UZ-normalized'!$A:$A, 0))-INDEX('UZ-normalized'!$E:$E, MATCH($A3, 'UZ-normalized'!$A:$A, 0))>0, -(30*INDEX('UZ-normalized'!$D:$D, MATCH($A3, 'UZ-normalized'!$A:$A, 0))-INDEX('UZ-normalized'!$E:$E, MATCH($A3, 'UZ-normalized'!$A:$A, 0))), 0), 0))) -> -340
