Workbook

Sheet TDSheet
A1: Артикул | B1: Заказ в шт
A2: PGGG006 | B2: 200
A3: PGGG007 | B3: 200
A4: PGGG030 | B4: 200
A5: PGGG031 | B5: 300
A6: PLAD001-S-0-D | B6: 7000
A7: PLAD001-S-0-N | B7: 400
A8: PLAD002-A-0-D | B8: 10500
A9: PLAD002-A-0-N | B9: 200
A10: PLAD004-A-0-D | B10: 11800
A11: PLAD004-A-0-N | B11: 2900
A12: PLAD005-S-0-D | B12: 4200
A13: PLAD005-S-0-N | B13: 1600
... A139: PX-REN-4A-3842-100-B | B139: 2

Sheet Лист2
A1: PGGG002
A2: PGGG006 | B2: 125
A3: PGGG007 | B3: 100
A4: PGGG030 | B4: 175
A5: PGGG031 | B5: 150
A6: PKAM001-S-0-H
A7: PKAM001-S-0-N
A8: PKAM001-S-0-N/6
A9: PKAM002-B-0-H
A10: PKAM002-B-0-N
A11: PKAM002-B-0-N/6
A12: PLAD001-S-0-D | B12: 1050
A13: PLAD001-S-0-N | B13: 75
A14: PLAD002-A-0-D | B14: 1525
A15: PLAD002-A-0-N | B15: 75
A16: PLAD003-S-0-D | B16: 25
A17: PLAD003-S-0-N | B17: 0
A18: PLAD004-A-0-D | B18: 3100
A19: PLAD004-A-0-N | B19: 550
A20: PLAD005-S-0-D | B20: 1700
A21: PLAD005-S-0-N | B21: 350
A22: PLAD006-S-0-N | B22: 450
A23: PLAD007-A-0-N | B23: 1250
... A27: PMOS002-A-0-D | B27: 0
A28: PMTZ001-S-0-D
A29: PMTZ002-B-0-N
A30: PMTZ003-S-0-N
A31: PSCA016-B-0-N
A32: PTMZ002-B-0-N
A33: PTMZ003-B-P-N
A34: PUAZ001-S-0-D
A35: PUAZ002-A-0-D
A36: PWOL002-A-0-D | B36: 0
A37: PWOL003-S-0-D | B37: 50
A38: PWOL003-S-0-N | B38: 0
A39: PWOL004-A-0-D | B39: 125
A40: PWOL004-A-0-N | B40: 0
A41: PWOL007-S-0-N | B41: 0
A42: PYAM001-S-0-N
A43: PYAM003-B-0-N
...

Sheet Лист1
A1: JCHE005-G-S-0 | B1: 10 | C1: =VLOOKUP(A1:A128,Лист2!A$1:A$353,2,0) -> #REF!
A2: JLAD011-G-S-0 | B2: 700 | C2: =VLOOKUP(A2:A129,Лист2!A$1:A$353,2,0) -> #REF!
A3: JLAD012-G-S-0 | B3: 850 | C3: =VLOOKUP(A3:A130,Лист2!A$1:A$353,2,0) -> #REF!
A4: JLAD013-G-S-0 | B4: 2385 | C4: =VLOOKUP(A4:A131,Лист2!A$1:A$353,2,0) -> #REF!
A5: JLAD014-G-S-0 | B5: 4275 | C5: =VLOOKUP(A5:A132,Лист2!A$1:A$353,2,0) -> #REF!
A6: JREN007-B-S-0 | B6: 5 | C6: =VLOOKUP(A6:A133,Лист2!A$1:A$353,2,0) -> #REF!
A7: JREN016-B-S-0 | B7: 40 | C7: =VLOOKUP(A7:A134,Лист2!A$1:A$353,2,0) -> #REF!
A8: JWOL003-G-P-0 | B8: 60 | C8: =VLOOKUP(A8:A135,Лист2!A$1:A$353,2,0) -> #REF!
A9: JWOL004-G-P-0 | B9: 60 | C9: =VLOOKUP(A9:A136,Лист2!A$1:A$353,2,0) -> #REF!
A10: JWOL004-G-P-1 | B10: 30 | C10: =VLOOKUP(A10:A137,Лист2!A$1:A$353,2,0) -> #REF!
A11: JWOL004-G-S-1 | B11: 60 | C11: =VLOOKUP(A11:A138,Лист2!A$1:A$353,2,0) -> #REF!
A12: PDAE006-A-0-N | B12: 10 | C12: =VLOOKUP(A12:A139,Лист2!A$1:A$353,2,0) -> #REF!
... A14: PDAE012-A-0-N | B14: 25 | C14: =VLOOKUP(A14:A141,Лист2!A$1:A$353,2,0) -> #REF!
A15: PLAD007-B-0-H | B15: 125 | C15: 125
A16: PLAD006-S-0-H | B16: 100 | C16: 100
A17: PLAD031-B-0-H | B17: 175 | C17: 175
A18: PLAD030-S-0-H | B18: 150 | C18: 150
A19: PLAD001-S-0-D | B19: 100 | C19: =VLOOKUP(A19:A146,Лист2!A$1:A$353,2,0) -> #REF!
A20: PLAD001-S-0-N | B20: 75 | C20: =VLOOKUP(A20:A147,Лист2!A$1:A$353,2,0) -> #REF!
A21: PLAD002-A-0-N | B21: 75 | C21: =VLOOKUP(A21:A148,Лист2!A$1:A$353,2,0) -> #REF!
A22: PLAD003-S-0-D | B22: 25 | C22: =VLOOKUP(A22:A149,Лист2!A$1:A$353,2,0) -> #REF!
A23: PLAD004-A-0-D | B23: 1175 | C23: =VLOOKUP(A23:A150,Лист2!A$1:A$353,2,0) -> #REF!
A24: PLAD005-S-0-D | B24: 1300 | C24: =VLOOKUP(A24:A151,Лист2!A$1:A$353,2,0) -> #REF!
A25: PLAD006-S-0-N | B25: 300 | C25: =VLOOKUP(A25:A152,Лист2!A$1:A$353,2,0) -> #REF!
A26: PLAD007-A-0-N | B26: 825 | C26: =VLOOKUP(A26:A153,Лист2!A$1:A$353,2,0) -> #REF!
A27: PLAD026-B-0-N | B27: 100 | C27: =VLOOKUP(A27:A154,Лист2!A$1:A$353,2,0) -> #REF!
A28: PREN001-S-0-D | B28: 75 | C28: =VLOOKUP(A28:A155,Лист2!A$1:A$353,2,0) -> #REF!
A29: PREN002-A-0-D | B29: 75 | C29: =VLOOKUP(A29:A156,Лист2!A$1:A$353,2,0) -> #REF!
A30: PREN018-S-0-0 | B30: 50 | C30: =VLOOKUP(A30:A157,Лист2!A$1:A$353,2,0) -> #REF!
... A33: PWOL004-A-0-D | B33: 125 | C33: =VLOOKUP(A33:A160,Лист2!A$1:A$353,2,0) -> #REF!
A34: PR-CHE-49-1590-000-SET | B34: 2 | C34: 2
A35: PR-CHE-49-3549-000-SET | B35: 3 | C35: 3
A36: PR-CHE-49-3549-025-SET | B36: 3 | C36: 3
A37: PR-DAE-49-3538-000-SET | B37: 10 | C37: =VLOOKUP(A37:A164,Лист2!A$1:A$353,2,0) -> #REF!
A38: PR-DAE-49-3538-025-SET | B38: 10 | C38: =VLOOKUP(A38:A165,Лист2!A$1:A$353,2,0) -> #REF!
A39: PR-DAE-49-3538-050-SET | B39: 5 | C39: =VLOOKUP(A39:A166,Лист2!A$1:A$353,2,0) -> #REF!
A40: PR-DAE-49-3548-000-SET | B40: 30 | C40: =VLOOKUP(A40:A167,Лист2!A$1:A$353,2,0) -> #REF!
A41: PR-LAD-44-2802-000-SET | B41: 50 | C41: =VLOOKUP(A41:A168,Лист2!A$1:A$353,2,0) -> #REF!
A42: PR-LAD-44-2802-040-SET | B42: 70 | C42: =VLOOKUP(A42:A169,Лист2!A$1:A$353,2,0) -> #REF!
A43: PR-LAD-44-2803-000-SET | B43: 40 | C43: =VLOOKUP(A43:A170,Лист2!A$1:A$353,2,0) -> #REF!
...
