Workbook

Sheet SKU
A1: SKU (ключ, унікальний) | B1: Name | C1: Brand | D1: Group1 | E1: Group2 | F1: UOM | G1: AssemblyQty | H1: Normalized-UA
A2: PR-CHE-49-1405-000-SET | B2: 1 | C2: =MID(A2,4,3) -> CHE | D2: =MID(A2,11,4) -> 1405 | E2: 19-1405-000 | F2: set | G2: =MID(A2,8,1) -> 4 | H2: 1
A3: PR-CHE-49-1405-025-SET | B3: 1 | C3: =MID(A3,4,3) -> CHE | D3: =MID(A3,11,4) -> 1405 | E3: 19-1405-025 | F3: set | G3: =MID(A3,8,1) -> 4 | H3: 1
A4: PR-CHE-49-1405-050-SET | B4: 1 | C4: =MID(A4,4,3) -> CHE | D4: =MID(A4,11,4) -> 1405 | E4: 19-1405-050 | F4: set | G4: =MID(A4,8,1) -> 4 | H4: 1
A5: PR-CHE-49-1590-000-SET | B5: 1 | C5: =MID(A5,4,3) -> CHE | D5: =MID(A5,11,4) -> 1590 | E5: 19-1590-000 | F5: set | G5: =MID(A5,8,1) -> 4 | H5: 1
A6: PR-CHE-49-1590-025-SET | B6: 1 | C6: =MID(A6,4,3) -> CHE | D6: =MID(A6,11,4) -> 1590 | E6: 19-1590-025 | F6: set | G6: =MID(A6,8,1) -> 4 | H6: 1
A7: PR-CHE-49-1590-050-SET | B7: 1 | C7: =MID(A7,4,3) -> CHE | D7: =MID(A7,11,4) -> 1590 | E7: 19-1590-050 | F7: set | G7: =MID(A7,8,1) -> 4 | H7: 1
A8: PR-CHE-47-3549-000-SET | B8: 1 | C8: =MID(A8,4,3) -> CHE | D8: =MID(A8,11,4) -> 3549 | E8: 17-3549-000 | F8: set | G8: =MID(A8,8,1) -> 4 | H8: 1
A9: PR-CHE-47-3549-025-SET | B9: 1 | C9: =MID(A9,4,3) -> CHE | D9: =MID(A9,11,4) -> 3549 | E9: 17-3549-025 | F9: set | G9: =MID(A9,8,1) -> 4 | H9: 1
A10: PR-CHE-47-3549-050-SET | B10: 1 | C10: =MID(A10,4,3) -> CHE | D10: =MID(A10,11,4) -> 3549 | E10: 17-3549-050 | F10: set | G10: =MID(A10,8,1) -> 4 | H10: 1
A11: PR-CHE-49-3549-000-SET | B11: 1 | C11: =MID(A11,4,3) -> CHE | D11: =MID(A11,11,4) -> 3549 | E11: 19-3549-000 | F11: set | G11: =MID(A11,8,1) -> 4 | H11: 1
A12: PR-CHE-49-3549-025-SET | B12: 1 | C12: =MID(A12,4,3) -> CHE | D12: =MID(A12,11,4) -> 3549 | E12: 19-3549-025 | F12: set | G12: =MID(A12,8,1) -> 4 | H12: 1
A13: PR-CHE-49-3549-050-SET | B13: 1 | C13: =MID(A13,4,3) -> CHE | D13: =MID(A13,11,4) -> 3549 | E13: 19-3549-050 | F13: set | G13: =MID(A13,8,1) -> 4 | H13: 1
... A248: PR-ZIL-84-5991-000-SET | B248: 1 | C248: =MID(A248,4,3) -> ZIL | D248: =MID(A248,11,4) -> 5991 | E248: 14-5991-000 | F248: set | G248: =MID(A248,8,1) -> 8 | H248: 1
A249: PCHE003-S-0-D | B249: 2 | C249: =MID(A249,2,3) -> CHE | D249: =LEFT(A249,7) -> PCHE003 | E249: =RIGHT(A249,5) -> S-0-D | F249: pc | G249: 1 | H249: 1
A250: PCHE005-S-0-D | B250: 2 | C250: =MID(A250,2,3) -> CHE | D250: =LEFT(A250,7) -> PCHE005 | E250: =RIGHT(A250,5) -> S-0-D | F250: pc | G250: 1 | H250: 4
A251: PCHE005-S-0-N | B251: 2 | C251: =MID(A251,2,3) -> CHE | D251: =LEFT(A251,7) -> PCHE005 | E251: =RIGHT(A251,5) -> S-0-N | F251: pc | G251: 1 | H251: 4
A252: PCHE006-A-0-D | B252: 2 | C252: =MID(A252,2,3) -> CHE | D252: =LEFT(A252,7) -> PCHE006 | E252: =RIGHT(A252,5) -> A-0-D | F252: pc | G252: 1 | H252: 4
A253: PCHE006-A-0-N | B253: 2 | C253: =MID(A253,2,3) -> CHE | D253: =LEFT(A253,7) -> PCHE006 | E253: =RIGHT(A253,5) -> A-0-N | F253: pc | G253: 1 | H253: 4
A254: PCHE007-S-0-D | B254: 2 | C254: =MID(A254,2,3) -> CHE | D254: =LEFT(A254,7) -> PCHE007 | E254: =RIGHT(A254,5) -> S-0-D | F254: pc | G254: 1 | H254: 4
A255: PCHE007-S-0-N | B255: 2 | C255: =MID(A255,2,3) -> CHE | D255: =LEFT(A255,7) -> PCHE007 | E255: =RIGHT(A255,5) -> S-0-N | F255: pc | G255: 1 | H255: 4
A256: PCHE008-A-0-D | B256: 2 | C256: =MID(A256,2,3) -> CHE | D256: =LEFT(A256,7) -> PCHE008 | E256: =RIGHT(A256,5) -> A-0-D | F256: pc | G256: 1 | H256: 4
A257: PCHE008-A-0-N | B257: 2 | C257: =MID(A257,2,3) -> CHE | D257: =LEFT(A257,7) -> PCHE008 | E257: =RIGHT(A257,5) -> A-0-N | F257: pc | G257: 1 | H257: 4
A258: PCHE013-S-0-N | B258: 2 | C258: =MID(A258,2,3) -> CHE | D258: =LEFT(A258,7) -> PCHE013 | E258: =RIGHT(A258,5) -> S-0-N | F258: pc | G258: 1 | H258: 1
A259: PCHE014-A-0-N | B259: 2 | C259: =MID(A259,2,3) -> CHE | D259: =LEFT(A259,7) -> PCHE014 | E259: =RIGHT(A259,5) -> A-0-N | F259: pc | G259: 1 | H259: 1
A260: PCHE033-S-0-N | B260: 2 | C260: =MID(A260,2,3) -> CHE | D260: =LEFT(A260,7) -> PCHE033 | E260: =RIGHT(A260,5) -> S-0-N | F260: pc | G260: 1 | H260: 4
... A390: PZIL002-B-0-N | B390: 2 | C390: =MID(A390,2,3) -> ZIL | D390: =LEFT(A390,7) -> PZIL002 | E390: =RIGHT(A390,5) -> B-0-N | F390: pc | G390: 1 | H390: 1
A391: JCAT005-G-S-0 | B391: 3 | C391: =MID(A391,2,3) -> CAT | D391: =LEFT(A391,7) -> JCAT005 | E391: =RIGHT(A391,1) -> 0 | F391: pc | G391: 1 | H391: 1
A392: JCHE003-G-S-0 | B392: 3 | C392: =MID(A392,2,3) -> CHE | D392: =LEFT(A392,7) -> JCHE003 | E392: =RIGHT(A392,1) -> 0 | F392: pc | G392: 1 | H392: 4
A393: JCHE003-G-S-1 | B393: 3 | C393: =MID(A393,2,3) -> CHE | D393: =LEFT(A393,7) -> JCHE003 | E393: =RIGHT(A393,1) -> 1 | F393: pc | G393: 1 | H393: 4
A394: JCHE004-G-S-0 | B394: 3 | C394: =MID(A394,2,3) -> CHE | D394: =LEFT(A394,7) -> JCHE004 | E394: =RIGHT(A394,1) -> 0 | F394: pc | G394: 1 | H394: 4
A395: JCHE004-G-S-1 | B395: 3 | C395: =MID(A395,2,3) -> CHE | D395: =LEFT(A395,7) -> JCHE004 | E395: =RIGHT(A395,1) -> 1 | F395: pc | G395: 1 | H395: 1
A396: JCHE005-G-S-0 | B396: 3 | C396: =MID(A396,2,3) -> CHE | D396: =LEFT(A396,7) -> JCHE005 | E396: =RIGHT(A396,1) -> 0 | F396: pc | G396: 1 | H396: 4
A397: JCHE005-G-S-1 | B397: 3 | C397: =MID(A397,2,3) -> CHE | D397: =LEFT(A397,7) -> JCHE005 | E397: =RIGHT(A397,1) -> 1 | F397: pc | G397: 1 | H397: 1
A398: JDAE001-G-P-0 | B398: 3 | C398: =MID(A398,2,3) -> DAE | D398: =LEFT(A398,7) -> JDAE001 | E398: =RIGHT(A398,1) -> 0 | F398: pc | G398: 1 | H398: 4
A399: JDAE001-G-S-0 | B399: 3 | C399: =MID(A399,2,3) -> DAE | D399: =LEFT(A399,7) -> JDAE001 | E399: =RIGHT(A399,1) -> 0 | F399: pc | G399: 1 | H399: 4
A400: JDAE001-G-S-1 | B400: 3 | C400: =MID(A400,2,3) -> DAE | D400: =LEFT(A400,7) -> JDAE001 | E400: =RIGHT(A400,1) -> 1 | F400: pc | G400: 1 | H400: 1
A401: JDAE003-G-P-0 | B401: 3 | C401: =MID(A401,2,3) -> DAE | D401: =LEFT(A401,7) -> JDAE003 | E401: =RIGHT(A401,1) -> 0 | F401: pc | G401: 1 | H401: 3
A402: JDAE003-G-S-0 | B402: 3 | C402: =MID(A402,2,3) -> DAE | D402: =LEFT(A402,7) -> JDAE003 | E402: =RIGHT(A402,1) -> 0 | F402: pc | G402: 1 | H402: 3
... A505: JZIL002-G-S-2 | B505: 3 | C505: =MID(A505,2,3) -> ZIL | D505: =LEFT(A505,7) -> JZIL002 | E505: =RIGHT(A505,1) -> 2 | F505: pc | G505: 1 | H505: 1
...

Sheet Name
A1: 1 | B1: Кільця
A2: 2 | B2: Клапани
A3: 3 | B3: Втулки
A4: 4 | B4: Пальці
A5: 5 | B5: Поршні
A6: 6 | B6: Гільзи
A7: 7 | B7: Свічки

Sheet Mapping
A1: Неправильный | B1: Артикул
A2: XWOL-406-GREEN | B2: XWOL-64-GREEN | C2: =VLOOKUP(B2,SKU!A:A,1,0) -> XWOL-64-GREEN
A3: XWOL-406-RED | B3: XWOL-64-RED | C3: =VLOOKUP(B3,SKU!A:A,1,0) -> XWOL-64-RED
A4: XWOL-406-WHITE | B4: XWOL-64-WHITE | C4: =VLOOKUP(B4,SKU!A:A,1,0) -> XWOL-64-WHITE
A5: XWOL-406-YELLOW | B5: XWOL-64-YELLOW | C5: =VLOOKUP(B5,SKU!A:A,1,0) -> XWOL-64-YELLOW
A6: XWOL-405-GREEN | B6: XWOL-67-GREEN | C6: =VLOOKUP(B6,SKU!A:A,1,0) -> XWOL-67-GREEN
A7: XWOL-405-RED | B7: XWOL-67-RED | C7: =VLOOKUP(B7,SKU!A:A,1,0) -> XWOL-67-RED
A8: XWOL-405-WHITE | B8: XWOL-67-WHITE | C8: =VLOOKUP(B8,SKU!A:A,1,0) -> XWOL-67-WHITE
A9: XWOL-405-YELLOW | B9: XWOL-67-YELLOW | C9: =VLOOKUP(B9,SKU!A:A,1,0) -> XWOL-67-YELLOW
A10: PR-SMD-44-6000-000-SET | B10: PR-SMD-44-0143-000-SET | C10: =VLOOKUP(B10,SKU!A:A,1,0) -> PR-SMD-44-0143-000-SET
A11: PR-SMD-44-6000-070-SET | B11: PR-SMD-44-0143-070-SET | C11: =VLOOKUP(B11,SKU!A:A,1,0) -> PR-SMD-44-0143-070-SET
A12: PR-SMD-47-6000-000-SET | B12: PR-SMD-44-0144-000-SET | C12: =VLOOKUP(B12,SKU!A:A,1,0) -> PR-SMD-44-0144-000-SET
A13: PR-SMD-47-6000-070-SET | B13: PR-SMD-44-0144-070-SET | C13: =VLOOKUP(B13,SKU!A:A,1,0) -> PR-SMD-44-0144-070-SET
... A66: D-21 | B66: D21 | C66: =VLOOKUP(B66,SKU!A:A,1,0) -> D21

Sheet Help
A1: | Поле | Повна назва | Що означає | Навіщо потрібно |
A2: | -------------- | ---------------------------------------------------------- | ------------------------------------------------------------------------------ | ------------------------------------------------------------------------------------------ |
A3: | **UOM** | *Unit of Measure* — одиниця виміру | Наприклад: `шт`, `компл`, `л`, `м` | Щоб розуміти, у чому обліковуються запаси, продажі, замовлення. |
A4: | **MOQ** | *Minimum Order Quantity* — мінімальна кількість замовлення | Наприклад: `10`, якщо постачальник відвантажує тільки кратно 10 | Для розрахунку **рекомендованого замовлення**, щоб не замовити менше ніж можливо. |
A5: | **LT_days** | *Lead Time (days)* — термін постачання в днях | Наприклад: `45` — товар іде 45 днів від замовлення до складу | Використовується у плануванні «заздалегідь» (коли треба зробити PO, щоб не було дефіциту). |
A6: | **SafetyDays** | *Safety Stock (days)* — запас безпеки в днях | Наприклад: `14` — додаткові дні попиту «на всяк випадок» | Визначає страховий запас (додається до потреби при розрахунках «Итого»). |
A7: | **Weight_kg** | Вага 1 одиниці SKU в кілограмах | Наприклад: `2.5` | Для логістики (розрахунок ваги замовлень, вартості перевезення). |
A8: | **Volume_m3** | Об’єм 1 одиниці SKU у кубічних метрах | Наприклад: `0.015` | Для планування заповнення контейнерів або складських площ. |
A9: | **Status** | Статус SKU (`Active`, `Inactive`, `Archived`) | Визначає, чи активний товар, тимчасово не постачається, чи знятий з обліку | Щоб фільтрувати позиції у звітах (наприклад, «замовляти лише Active»). |
A10: | **StartDate** | Дата початку активності SKU | Наприклад: `2024-01-01` | Коли товар з’явився у продажу (для аналітики або прогнозу). |
A11: | **EndDate** | Дата закінчення активності | Наприклад: `2025-06-30` | Коли товар буде знятий із постачання (не замовляти після цієї дати). |
A12: | **Notes** | Примітки | Будь-які додаткові пояснення, наприклад «новий артикул», «заміна старого» тощо | Для ручних коментарів або уточнень ВНС / постачальників. |

Sheet New
